Workbook

Sheet DiagnosticSessionControl_0x10
B1: Test Level | C1: SYS.5
A2: Sequence Number | B2: System Requirement ID | C2: Test Case | G2: Design Method | H2: Precondition | I2: Test Procedure | J2: Expected Output | K2: Actual Output | L2: Judgement Result | M2: Defect ID
C3: ID | D3: Name | E3: Priority | F3: Author
A4: 1.Application Service\_Physical Addressing
A5: 1.1 Session Layer Test
A6: 1 | B6: 1.General 2.DiagnosticServices | C6: Diag_0x10_Phy_001 | D6: Service 0x10 Default To Default | E6: High | F6: 陈亚-80025578 | G6: Based on analysis of requirements | H6: 1.Power On; | I6: 1.Send DiagBy[Physical]Data[10 01]; 2.Send DiagBy[Physical]Data[10 01]; | J6: 1.Check DiagData[50 01 00 32 01 F4]Within[50]ms; 2.Check DiagData[50 01 00 32 01 F4]Within[50]ms; | L6: Pass
A7: 2 | B7: 1.General 2.DiagnosticServices | C7: Diag_0x10_Phy_002 | D7: Service 0x10 Default To Programming | E7: High | F7: 陈亚-80025578 | G7: Based on analysis of requirements | H7: 1.Power On; | I7: 1.Send DiagBy[Physical]Data[10 01]; 2.Send DiagBy[Physical]Data[10 02]; | J7: 1.Check DiagData[50 01 00 32 01 F4]Within[50]ms; 2.Check DiagData[7F 10 7E]Within[50]ms; | K7: 默认会话到编程会话，应该恢复NRC 0x7E | L7: Fail
A8: 3 | B8: 1.General 2.DiagnosticServices | C8: Diag_0x10_Phy_003 | D8: Service 0x10 Default To Extended | E8: High | F8: 陈亚-80025578 | G8: Based on analysis of requirements | H8: 1.Power On; | I8: 1.Send DiagBy[Physical]Data[10 01]; 2.Send DiagBy[Physical]Data[10 03]; | J8: 1.Check DiagData[50 01 00 32 01 F4]Within[50]ms; 2.Check DiagData[50 03 00 32 01 F4]Within[50]ms; | L8: Pass
A9: 4 | B9: 1.General 2.DiagnosticServices | C9: Diag_0x10_Phy_004 | D9: Programming Session to Default Session PositiveCase-$10 | E9: High | F9: Chris | G9: Based on analysis of requirements | H9: 1.Power On | I9: 1.Send DiagBy[Physical]Data[10 01]; 2.Send DiagBy[Physical]Data[10 03]; 4.Send DiagBy[Physical]Data[10 02]; 5.Send DiagBy[Physical]Data[10 01]; | J9: 1.Check DiagData[50 01 00 32 01 F4]Within[50]ms; 2.Check DiagData[50 03 00 32 01 F4]Within[50]ms; 4.Check DiagData[50 02 00 32 01 F4]Within[50]ms; 5.Check DiagData[50 01 00 32 01 F4]Within[50]ms; | K9: 会话跳转缺失编程开始的场景 | L9: Block
A10: 5 | B10: 1.General 2.DiagnosticServices | C10: Diag_0x10_Phy_005 | D10: Programming Session to Programming Session PositiveCase-$10 | E10: High | F10: Chris | G10: Based on analysis of requirements | H10: 1.Power On | I10: 1.Send DiagBy[Physical]Data[10 01]; 2.Send DiagBy[Physical]Data[10 03]; 4.Send DiagBy[Physical]Data[10 02]; 5.Send DiagBy[Physical]Data[10 02]; | J10: 1.Check DiagData[50 01 00 32 01 F4]Within[50]ms; 2.Check DiagData[50 03 00 32 01 F4]Within[50]ms; 4.Check DiagData[50 02 00 32 01 F4]Within[50]ms; 5.Check DiagData[50 02 00 32 01 F4]Within[50]ms; | L10: Block
A11: 6 | B11: 1.General 2.DiagnosticServices | C11: Diag_0x10_Phy_006 | D11: Programming Session to Extended Session PositiveCase-$10 | E11: High | F11: Chris | G11: Based on analysis of requirements | H11: 1.Power On | I11: 1.Send DiagBy[Physical]Data[10 01]; 2.Send DiagBy[Physical]Data[10 03]; 4.Send DiagBy[Physical]Data[10 02]; 5.Send DiagBy[Physical]Data[10 03]; | J11: 1.Check DiagData[50 01 00 32 01 F4]Within[50]ms; 2.Check DiagData[50 03 00 32 01 F4]Within[50]ms; 4.Check DiagData[50 02 00 32 01 F4]Within[50]ms; 5.Check DiagData[7F 10 7E]Within[50]ms; | L11: Block
A12: 7 | B12: 1.General 2.DiagnosticServices | C12: Diag_0x10_Phy_007 | D12: Service 0x10 Extended To Default | E12: High | F12: 陈亚-80025578 | G12: Based on analysis of requirements | H12: 1.Power On; | I12: 1.Send DiagBy[Physical]Data[10 01]; 2.Delay[1000]ms; 3.Send DiagBy[Physical]Data[10 03]; 4.Send DiagBy[Physical]Data[10 01]; | J12: 1.Check DiagData[50 01 00 32 01 F4]Within[50]ms; 3.Check DiagData[50 03 00 32 01 F4]Within[50]ms; 4.Check DiagData[50 01 00 32 01 F4]Within[50]ms; | L12: Pass
A13: 8 | B13: 1.General 2.DiagnosticServices | C13: Diag_0x10_Phy_008 | D13: Service 0x10 Extended To Programming | E13: High | F13: 陈亚-80025578 | G13: Based on analysis of requirements | H13: 1.Power On; | I13: 1.Send DiagBy[Physical]Data[10 01]; 2.Delay[1000]ms; 3.Send DiagBy[Physical]Data[10 03]; 5.Send DiagBy[Physical]Data[10 02]; | J13: 1.Check DiagData[50 01 00 32 01 F4]Within[50]ms; 3.Check DiagData[50 03 00 32 01 F4]Within[50]ms; 5.Check DiagData[50 02 00 32 01 F4]Within[50]ms; | K13: 不支持31 01 02 03 | L13: Fail
A14: 9 | B14: 1.General 2.DiagnosticServices | C14: Diag_0x10_Phy_009 | D14: Service 0x10 Extended To Extended | E14: High | F14: 陈亚-80025578 | G14: Based on analysis of requirements | H14: 1.Power On; | I14: 1.Send DiagBy[Physical]Data[10 01]; 2.Delay[1000]ms; 3.Send DiagBy[Physical]Data[10 03]; 4.Send DiagBy[Physical]Data[10 03]; | J14: 1.Check DiagData[50 01 00 32 01 F4]Within[50]ms; 3.Check DiagData[50 03 00 32 01 F4]Within[50]ms; 4.Check DiagData[50 03 00 32 01 F4]Within[50]ms; | L14: Pass
A15: 1.2 SPRMIB Test
A16: 10 | B16: 1.General 2.DiagnosticServices | C16: Diag_0x10_Phy_010 | D16: Default Session to Default Session with SPRMIB PositiveCase-$10 | E16: High | F16: 陈亚-80025578 | G16: Based on analysis of requirements | H16: 1.Power On | I16: 1.Send DiagBy[Physical]Data[10 01]; 2.Send DiagBy[Physical]Data[10 81]; | J16: 1.Check DiagData[50 01 00 32 01 F4]Within[50]ms; 2.Check No_Response Within[1000]ms; | L16: Pass
A17: 11 | B17: 1.General 2.DiagnosticServices | C17: Diag_0x10_Phy_011 | D17: Default Session to Programming Session with SPRMIB NegativeCase-$10 | E17: High | F17: 陈亚-80025578 | G17: Based on analysis of requirements | H17: 1.Power On | I17: 1.Send DiagBy[Physical]Data[10 01]; 2.Send DiagBy[Physical]Data[10 82]; | J17: 1.Check DiagData[50 01 00 32 01 F4]Within[50]ms; 2.Check DiagData[7F 10 7E]Within[50]ms; | L17: Pass
A18: 12 | B18: 1.General 2.DiagnosticServices | C18: Diag_0x10_Phy_012 | D18: Default Session to Extended Session with SPRMIB PositiveCase-$10 | E18: High | F18: 陈亚-80025578 | G18: Based on analysis of requirements | H18: 1.Power On | I18: 1.Send DiagBy[Physical]Data[10 01]; 2.Delay[5000]ms; 3.Send DiagBy[Physical]Data[10 83]; | J18: 1.Check DiagData[50 01 00 32 01 F4]Within[50]ms; 3.Check No_Response Within[1000]ms; | L18: Pass
A19: 13 | B19: 1.General 2.DiagnosticServices | C19: Diag_0x10_Phy_013 | D19: Programming Session to Programming Session with SPRMIB PositiveCase-$10 | E19: High | F19: 陈亚-80025578 | G19: Based on analysis of requirements | H19: 1.Power On | I19: 1.Send DiagBy[Physical]Data[10 01]; 2.Delay[5000]ms; 3.Send DiagBy[Physical]Data[10 03]; 4.Send DiagBy[Physical]Data[10 02]; 5.Send DiagBy[Physical]Data[10 81]; | J19: 1.Check DiagData[50 01 00 32 01 F4]Within[50]ms; 3.Check DiagData[50 03 00 32 01 F4]Within[50]ms; 4.Check DiagData[50 02 00 32 01 F4]Within[50]ms; 5.Check No_Response Within[1000]ms; | L19: Block
A20: 14 | B20: 1.General 2.DiagnosticServices | C20: Diag_0x10_Phy_014 | D20: Programming Session to Programming Session with SPRMIB PositiveCase-$10 | E20: High | F20: 陈亚-80025578 | G20: Based on analysis of requirements | H20: 1.Power On | I20: 1.Send DiagBy[Physical]Data[10 01]; 2.Delay[3000]ms; 3.Send DiagBy[Physical]Data[10 03]; 4.Send DiagBy[Physical]Data[10 02]; 5.Send DiagBy[Physical]Data[10 82]; | J20: 1.Check DiagData[50 01 00 32 01 F4]Within[50]ms; 3.Check DiagData[50 03 00 32 01 F4]Within[50]ms; 4.Check DiagData[50 02 00 32 01 F4]Within[50]ms; 5.Check DiagData[7F 10 12]Within[50]ms; | L20: Block
A21: 15 | B21: 1.General 2.DiagnosticServices | C21: Diag_0x10_Phy_015 | D21: Programming Session to Extented Session with SPRMIB PositiveCase-$10 | E21: High | F21: 陈亚-80025578 | G21: Based on analysis of requirements | H21: 1.Power On | I21: 1.Send DiagBy[Physical]Data[10 01]; 2.Delay[5000]ms; 3.Send DiagBy[Physical]Data[10 03]; 4.Send DiagBy[Physical]Data[10 02]; 5.Send DiagBy[Physical]Data[10 83]; | J21: 1.Check DiagData[50 01 00 32 01 F4]Within[50]ms; 3.Check DiagData[50 03 00 32 01 F4]Within[50]ms; 4.Check DiagData[50 02 00 32 01 F4]Within[50]ms; 5.Check DiagData[7F 10 22]Within[50]ms; | L21: Block
A22: 16 | B22: 1.General 2.DiagnosticServices | C22: Diag_0x10_Phy_016 | D22: Extended Session to Default Session with SPRMIB PositiveCase-$10 | E22: High | F22: 陈亚-80025578 | G22: Based on analysis of requirements | H22: 1.Power On | I22: 1.Send DiagBy[Physical]Data[10 01]; 2.Delay[5000]ms 3.Send DiagBy[Physical]Data[10 03]; 4.Send DiagBy[Physical]Data[10 81]; | J22: 1.Check DiagData[50 01 00 32 01 F4]Within[50]ms; 3.Check DiagData[50 03 00 32 01 F4]Within[50]ms; 4.Check No_Response Within[1000]ms; | L22: Pass
A23: 17 | B23: 1.General 2.DiagnosticServices | C23: Diag_0x10_Phy_017 | D23: Extended Session to Programming Session with SPRMIB PositiveCase-$10 | E23: High | F23: 陈亚-80025578 | G23: Based on analysis of requirements | H23: 1.Power On | I23: 1.Send DiagBy[Physical]Data[10 03]; 2.Send DiagBy[Physical]Data[10 82]; | J23: 1.Check DiagData[50 03 00 32 01 F4]Within[50]ms; 2.Check No_Response Within[1000]ms; | L23: Pass
A24: 18 | B24: 1.General 2.DiagnosticServices | C24: Diag_0x10_Phy_018 | D24: Extended Session to Extended Session with SPRMIB PositiveCase-$10 | E24: High | F24: 陈亚-80025578 | G24: Based on analysis of requirements | H24: 1.Power On | I24: 1.Send DiagBy[Physical]Data[10 03]; 2.Send DiagBy[Physical]Data[10 83]; 3.Send DiagBy[Physical]Data[22 F1 86]; | J24: 1.Check DiagData[50 03 00 32 01 F4]Within[50]ms; 2.Check No_Response Within[1000]ms; 3.Check DiagData[62 F1 86 03]Within[50]ms; | L24: Pass
A25: 1.3 Secure Access Test
A26: 19 | B26: 1.General 2.DiagnosticServices | C26: Diag_0x10_Phy_019 | D26: Security access L1 unlock supports jumping to Default Session | E26: High | F26: 陈亚-80025578 | G26: Based on analysis of requirements | H26: 1.Power On; | I26: 1.Send DiagBy[Physical]Data[10 03]; 2.Send DiagBy[Physical]Data[27 01]AndCheckResp[PositiveResponse]; 3.Send Security Right KeyBy[Physical]Level[0x2] 4.Send DiagBy[Physical]Data[10 01]; | J26: 1.Check DiagData[50 03 00 32 01 F4]Within[50]ms; 3.Check DiagData[67 02]Within[50]ms; 4.Check DiagData[50 01 00 32 01 F4]Within[50]ms; | K26: 缺失会话跳转中的01 ，02 | L26: Block
A27: 20 | B27: 1.General 2.DiagnosticServices | C27: Diag_0x10_Phy_020 | D27: Security access L1 unlock supports jumping to Programming Session | E27: High | F27: 陈亚-80025578 | G27: Based on analysis of requirements | H27: 1.Power On; | I27: 1.Send DiagBy[Physical]Data[10 03]; 2.Send DiagBy[Physical]Data[27 01]AndCheckResp[PositiveResponse]; 3.Send Security Right KeyBy[Physical]Level[0x2] 4.Send DiagBy[Physical]Data[10 02]; | J27: 1.Check DiagData[50 03 00 32 01 F4]Within[50]ms; 3.Check DiagData[67 02]Within[50]ms; 4.Check DiagData[50 02 00 32 01 F4]Within[50]ms; | L27: Block
A28: 21 | B28: 1.General 2.DiagnosticServices | C28: Diag_0x10_Phy_021 | D28: Security access L1 unlock supports jumping to Extended Session | E28: High | F28: 陈亚-80025578 | G28: Based on analysis of requirements | H28: 1.Power On; | I28: 1.Send DiagBy[Physical]Data[10 01]; 2.Delay[2000]ms; 3.Send DiagBy[Physical]Data[10 03]; 4.Send DiagBy[Physical]Data[27 01]AndCheckResp[PositiveResponse]; 5.Send Security Right KeyBy[Physical]Level[0x2] 6.Send DiagBy[Physical]Data[10 03]; | J28: 1.Check DiagData[50 01 00 32 01 F4]Within[50]ms; 3.Check DiagData[50 03 00 32 01 F4]Within[50]ms; 5.Check DiagData[67 02]Within[100]ms; 6.Check DiagData[50 03 00 32 01 F4]Within[50]ms; | L28: Pass
A29: 1.4 ECU Reset Test
A30: 22 | B30: 1.General 2.DiagnosticServices | C30: Diag_0x10_Phy_022 | D30: ECU Power reset Session returns to the Default Session | E30: Low | F30: 陈亚-80025578 | G30: Based on analysis of requirements | H30: 1.Power On; | I30: 1.Send DiagBy[Physical]Data[10 01]; 2.Delay[1000]ms; 3.Send DiagBy[Physical]Data[10 03]; 4.Set Voltage[0]V; 5.Delay[3000]ms; 6.Set Voltage[12]V; 7.Delay[3000]ms; 8.Send DiagBy[Physical]Data[27 01]AndCheckResp[0x7F]; | J30: 1.Check DiagData[50 01 00 32 01 F4]Within[50]ms; 3.Check DiagData[50 03 00 32 01 F4]Within[50]ms; | L30: Pass
A31: 23 | B31: 1.General 2.DiagnosticServices | C31: Diag_0x10_Phy_023 | D31: ECU Hard Reset reset Session returns to the Default Session | E31: Low | F31: 陈亚-80025578 | G31: Based on analysis of requirements | H31: 1.Power On; | I31: 1.Send DiagBy[Physical]Data[10 01]; 2.Delay[1000]ms; 3.Send DiagBy[Physical]Data[10 03]; 4.Send DiagBy[Physical]Data[11 01]; 5.Delay[1000]ms; 6.Send DiagBy[Physical]Data[27 01]AndCheckResp[0x7F]; | J31: 1.Check DiagData[50 01 00 32 01 F4]Within[50]ms; 3.Check DiagData[50 03 00 32 01 F4]Within[50]ms; 4.Check DiagData[51 01]Within[50]ms; | K31: 不支持F1 86,验证策略可以改成访问27安全服务，例如：Send DiagBy[Physical]Data[27 01]AndCheckResp[0x7F]; | L31: Fail
A32: 1.5 Sub-function Traversal Test
A33: 24 | B33: 1.General 2.DiagnosticServices | C33: Diag_0x10_Phy_024 | D33: Subfunction traversal test in the Default Session | E33: Medium | F33: 陈亚-80025578 | G33: Based on analysis of requirements | H33: 1.Power On; | I33: 1.Send DiagBy[Physical]Data[10 01]; 2.Send SubTraversalBy[Physical]Service[0x10]Excluding[01 02 03 81 83]AndCheckResp[0x12]; | J33: 1.Check DiagData[50 01 00 32 01 F4]Within[50]ms; | L33: Pass
A34: 25 | B34: 1.General 2.DiagnosticServices | C34: Diag_0x10_Phy_025 | D34: Subfunction traversal test in the Extended Session | E34: Medium | F34: 陈亚-80025578 | G34: Based on analysis of requirements | H34: 1.Power On; | I34: 1.Send DiagBy[Physical]Data[10 01]; 2.Delay[1000]ms; 3.Send DiagBy[Physical]Data[10 03]; 4.Send SubTraversalBy[Physical]Service[0x10]Excluding[01 02 03 81 83]AndCheckResp[0x12]; | J34: 1.Check DiagData[50 01 00 32 01 F4]Within[50]ms; 3.Check DiagData[50 03 00 32 01 F4]Within[50]ms; | L34: Pass
A35: 1.6 S3 Server Timer Test
A36: 26 | B36: 1.General 2.DiagnosticServices | C36: Diag_0x10_Phy_026 | D36: S3Server maintains the Session without timeout | E36: High | F36: 陈亚-80025578 | G36: Based on analysis of requirements | H36: 1.Power On; | I36: 1.Send DiagBy[Physical]Data[10 01]; 2.Delay[1000]ms; 3.Send DiagBy[Physical]Data[10 03]; 4.Delay[4900]ms; 5.Send DiagBy[Physical]Data[27 01]AndCheckResp[PositiveResponse]; | J36: 1.Check DiagData[50 01 00 32 01 F4]Within[50]ms; 3.Check DiagData[50 03 00 32 01 F4]Within[50]ms; | L36: Pass
A37: 27 | B37: 1.General 2.DiagnosticServices | C37: Diag_0x10_Phy_027 | D37: S3Server returns to the default Session upon timeout | E37: High | F37: 陈亚-80025578 | G37: Based on analysis of requirements | H37: 1.Power On; | I37: 1.Send DiagBy[Physical]Data[10 01]; 2.Delay[1000]ms; 3.Send DiagBy[Physical]Data[10 03]; 4.Delay[5100]ms; 5.Send DiagBy[Physical]Data[27 01]AndCheckResp[0x7F]; | J37: 1.Check DiagData[50 01 00 32 01 F4]Within[50]ms; 3.Check DiagData[50 03 00 32 01 F4]Within[50]ms; | L37: Pass
A38: 1.7 Incorrect Diagnostic Command Test
A39: 28 | B39: 1.General 2.DiagnosticServices | C39: Diag_0x10_Phy_028 | D39: Valid SF_DL=2, invalid SF_DL > 2 returns NRC 0x13 | E39: Low | F39: 陈亚-80025578 | G39: Based on analysis of requirements | H39: 1.Power On; | I39: 1.Send DiagBy[Physical]Data[10 01]; 2.Send DiagBy[Physical]Data[10 01]WithLen[3]; | J39: 1.Check DiagData[50 01 00 32 01 F4]Within[50]ms; 2.Check DiagData[7F 10 13]Within[50]ms; | L39: Pass
A40: 29 | B40: 1.General 2.DiagnosticServices | C40: Diag_0x10_Phy_029 | D40: Valid SF_DL=2, invalid SF_DL < 2 returns NRC 0x13 | E40: Low | F40: 陈亚-80025578 | G40: Based on analysis of requirements | H40: 1.Power On; | I40: 1.Send DiagBy[Physical]Data[10 01]; 2.Send DiagBy[Physical]Data[10 01]WithLen[1]; | J40: 1.Check DiagData[50 01 00 32 01 F4]Within[50]ms; 2.Check DiagData[7F 10 13]Within[50]ms; | L40: Pass
...

Sheet ECUReset_0x11
B1: Test Level | C1: SYS.5
A2: Sequence Number | B2: System Requirement ID | C2: Test Case | G2: Design Method | H2: Precondition | I2: Test Procedure | J2: Expected Output | K2: Actual Output | L2: Judgement Result | M2: Defect ID
C3: ID | D3: Name | E3: Priority | F3: Author
A4: 1.Application Service_Physical Addressing
A5: 1.1 Session Layer Test
A6: 1 | B6: 1.General 2.DiagnosticServices | C6: Diag_0x11_Phy_001 | D6: Default Session nonsupport 0x11 services | E6: High | F6: 陈亚-80025578 | G6: Based on analysis of requirements | H6: 1.Power On; | I6: 1.Send DiagBy[Physical]Data[10 01]; 2.Send DiagBy[Physical]Data[11 01]; 3.Delay[1000]ms; | J6: 1.Check DiagData[50 01 00 32 00 C8]Within[50]ms; 2.Check DiagData[7F 11 7F]Within[50]ms; | K6: 测试步骤中不应该出现step 1: | L6: Fail
A7: 2 | B7: 1.General 2.DiagnosticServices | C7: Diag_0x11_Phy_002 | D7: Programming Session support the 0x11 service 0x01 subfunction | E7: High | F7: 陈亚-80025578 | G7: Based on analysis of requirements | H7: 1.Power On; | I7: 1.Send DiagBy[Physical]Data[10 01]; 2.Delay[1000]ms; 3.Send DiagBy[Physical]Data[10 03]; 5.Send DiagBy[Physical]Data[10 02]; 6.Send DiagBy[Physical]Data[11 01]; 7.Delay[1000]ms; | J7: 1.Check DiagData[50 01 00 32 00 C8]Within[50]ms; 3.Check DiagData[50 03 00 32 00 C8]Within[50]ms; 5.Check DiagData[50 02 00 32 00 C8]Within[50]ms; 6.Check DiagData[51 01]Within[50]ms; | L7: Pass
A8: 3 | B8: 1.General 2.DiagnosticServices | C8: Diag_0x11_Phy_003 | D8: Extended Session support the 0x11 service 0x01 subfunction | E8: High | F8: 陈亚-80025578 | G8: Based on analysis of requirements | H8: 1.Power On; | I8: 1.Send DiagBy[Physical]Data[10 03]; 2.Send DiagBy[Physical]Data[11 01]; 3.Delay[1000]ms; | J8: 1.Check DiagData[50 03 00 32 00 C8]Within[50]ms; 2.Check DiagData[51 01]Within[50]ms; | L8: Pass
A9: 1.2 SPRMIB Test
A10: 4 | B10: 1.General 2.DiagnosticServices | C10: Diag_0x11_Phy_004 | D10: Default Session nonsupport 0x11 services with SPRMIB | E10: High | F10: 陈亚-80025578 | G10: Based on analysis of requirements | H10: 1.Power On; | I10: 1.Send DiagBy[Physical]Data[10 01]; 2.Send DiagBy[Physical]Data[11 81]; 3.Delay[1000]ms; | J10: 1.Check DiagData[50 01 00 32 00 C8]Within[50]ms; 2.Check DiagData[7F 11 12]Within[50]ms; | K10: 根据需求，suppressPosRspMsgIndicationBit= TRUE (1) (No response) 说明不支持抑制位，所以这里需要回复NRC 12 | L10: Fail
A11: 5 | B11: 1.General 2.DiagnosticServices | C11: Diag_0x11_Phy_005 | D11: Programming Session support the 0x11 service 0x01 subfunction with SPRMIB | E11: High | F11: 陈亚-80025578 | G11: Based on analysis of requirements | H11: 1.Power On; | I11: 1.Send DiagBy[Physical]Data[10 01]; 2.Delay[1000]ms; 3.Send DiagBy[Physical]Data[10 03]; 5.Send DiagBy[Physical]Data[10 02]; 6.Send DiagBy[Physical]Data[11 81]; 7.Delay[1000]ms; | J11: 1.Check DiagData[50 01 00 32 00 C8]Within[50]ms; 3.Check DiagData[50 03 00 32 00 C8]Within[50]ms; 5.Check DiagData[50 02 00 32 00 C8]Within[50]ms; 6.Check DiagData[7F 11 12]Within[50]ms; | K11: 根据需求，suppressPosRspMsgIndicationBit= TRUE (1) (No response) 说明不支持抑制位，所以这里需要回复NRC 12 | L11: Fail
A12: 6 | B12: 1.General 2.DiagnosticServices | C12: Diag_0x11_Phy_006 | D12: Extended Session support the 0x11 service 0x01 subfunction with SPRMIB | E12: High | F12: 陈亚-80025578 | G12: Based on analysis of requirements | H12: 1.Power On; | I12: 1.Send DiagBy[Physical]Data[10 03]; 2.Send DiagBy[Physical]Data[11 81]; 3.Delay[1000]ms; | J12: 1.Check DiagData[50 03 00 32 00 C8]Within[50]ms; 2.Check DiagData[7F 11 12]Within[50]ms; | K12: 根据需求，suppressPosRspMsgIndicationBit= TRUE (1) (No response) 说明不支持抑制位，所以这里需要回复NRC 12 | L12: Fail
A13: 1.3 Secure Access Test
A14: 7 | B14: 1.General 2.DiagnosticServices | C14: Diag_0x11_Phy_007 | D14: Security access L1 unlock supports 0x11 service 0x01 subfunction | E14: High | F14: 陈亚-80025578 | G14: Based on analysis of requirements | H14: 1.Power On; | I14: 1.Send DiagBy[Physical]Data[10 03]; 2.Send DiagBy[Physical]Data[27 01]AndCheckResp[PositiveResponse]; 3.Send Security Right KeyBy[Physical]Level[02]; 4.Send DiagBy[Physical]Data[11 01]; 5.Delay[1000]ms; | J14: 1.Check DiagData[50 03 00 32 00 C8]Within[50]ms; 3.Check DiagData[67 02]Within[50]ms; 4.Check DiagData[51 01]Within[50]ms; | L14: Pass
A15: 1.4.1 Service Reset
A16: 8 | B16: 1.General 2.DiagnosticServices | C16: Diag_0x11_Phy_008 | D16: 0x11 Service 0x01 subfunction non-Default Session to Default Session | E16: High | F16: 陈亚-80025578 | G16: Based on analysis of requirements | H16: 1.Power On; | I16: 1.Send DiagBy[Physical]Data[10 03]; 2.Send DiagBy[Physical]Data[11 01]; 3.Delay[1000]ms; | J16: 1.Check DiagData[50 03 00 32 00 C8]Within[50]ms; 2.Check DiagData[51 01]Within[50]ms; | L16: Pass
A17: 1.4.2 Security Access Reset
A18: 9 | B18: 1.General 2.DiagnosticServices | C18: Diag_0x11_Phy_009 | D18: 0x11 Service 0x01 subfunction Security access reset | E18: High | F18: 陈亚-80025578 | G18: Based on analysis of requirements | H18: 1.Power On; | I18: 1.Send DiagBy[Physical]Data[10 03]; 2.Send DiagBy[Physical]Data[27 01]AndCheckResp[PositiveResponse]; 3.Send Security Right KeyBy[Physical]Level[02]; 4.Send DiagBy[Physical]Data[11 01]; 5.Delay[1000]ms; 7.Send DiagBy[Physical]Data[27 01]; | J18: 1.Check DiagData[50 03 00 32 00 C8]Within[50]ms; 3.Check DiagData[67 02]Within[50]ms; 4.Check DiagData[51 01]Within[50]ms; 7.Check DiagData[7F 27 7F]Within[50]ms; | L18: Pass
A19: 1.4.3 Communication Control State Reset
A20: 10 | B20: 1.General 2.DiagnosticServices | C20: Diag_0x11_Phy_010 | D20: 0x11 Service 0x01 subfunction communication control state reset | E20: High | F20: 陈亚-80025578 | G20: Based on analysis of requirements | H20: 1.Power On; | I20: 1.Send DiagBy[Physical]Data[10 03]; 2.Send DiagBy[Physical]Data[28 01 01]; 3.Send DiagBy[Physical]Data[11 01]; 4.Delay[1000]ms; | J20: 1.Check DiagData[50 03 00 32 00 C8]Within[50]ms; 2.Check DiagData[68 01]Within[50]ms; Check MsgInexist[0x21F]; 3.Check DiagData[51 01]Within[50]ms; Check MsgExist[0x21F]; | K20: 测试过程中，不能出现结果检查 | L20: Fail
A21: 1.5 Sub-function Traversal Test
A22: 11 | B22: 1.General 2.DiagnosticServices | C22: Diag_0x11_Phy_011 | D22: Subfunction traversal test in the Default Session | E22: Medium | F22: 陈亚-80025578 | G22: Based on analysis of requirements | H22: 1.Power On; | I22: 1.Send DiagBy[Physical]Data[10 01]; 2.Send SubTraversalBy[Physical]Service[0x11]Excluding[01 81]AndCheckResp[0x7F]; | J22: 1.Check DiagData[50 01 00 32 00 C8]Within[50]ms; | L22: Pass
A23: 12 | B23: 1.General 2.DiagnosticServices | C23: Diag_0x11_Phy_012 | D23: Subfunction traversal test in the Programming Session | E23: Medium | F23: 陈亚-80025578 | G23: Based on analysis of requirements | H23: 1.Power On; | I23: 1.Send DiagBy[Physical]Data[10 01]; 2.Delay[1000]ms; 3.Send DiagBy[Physical]Data[10 03]; 5.Send DiagBy[Physical]Data[10 02]; 6.Send SubTraversalBy[Physical]Service[0x11]Excluding[01 81]AndCheckResp[0x12]; | J23: 1.Check DiagData[50 01 00 32 00 C8]Within[50]ms; 3.Check DiagData[50 03 00 32 00 C8]Within[50]ms; 5.Check DiagData[50 02 00 32 00 C8]Within[50]ms; | L23: Pass
A24: 13 | B24: 1.General 2.DiagnosticServices | C24: Diag_0x11_Phy_013 | D24: Subfunction traversal test in the Extended Session | E24: Medium | F24: 陈亚-80025578 | G24: Based on analysis of requirements | H24: 1.Power On; | I24: 1.Send DiagBy[Physical]Data[10 03]; 2.Send SubTraversalBy[Physical]Service[0x11]Excluding[01 81]AndCheckResp[0x12]; | J24: 1.Check DiagData[50 03 00 32 00 C8]Within[50]ms; | L24: Pass
A25: SF_DL Error Test
A26: 14 | B26: 1.General 2.DiagnosticServices | C26: Diag_0x11_Phy_014 | D26: Valid SF_DL=2, invalid SF_DL > 2, and those with invalid equivalence class SF_DL=3 NegativeCase-$11 | E26: Low | F26: 陈亚-80025578 | G26: Based on analysis of requirements | H26: 1.Power On; | I26: 1.Send DiagBy[Physics]Data[10 03]; 2.Send DiagBy[Physics]Data[11 01]WithLen[3]; | J26: 1.Check DiagData[50 03 00 32 00 C8]Within[50]ms; 2.Check DiagData[7F 11 13]Within[50]ms; | L26: Pass
A27: 15 | B27: 1.General 2.DiagnosticServices | C27: Diag_0x11_Phy_015 | D27: Valid SF_DL=2, invalid SF_DL < 2, and those with invalid equivalence class SF_DL=1 NegativeCase-$11 | E27: Low | F27: 陈亚-80025578 | G27: Based on analysis of requirements | H27: 1.Power On; | I27: 1.Send DiagBy[Physics]Data[10 03]; 2.Send DiagBy[Physics]Data[11 01]WithLen[1]; | J27: 1.Check DiagData[50 03 00 32 00 C8]Within[50]ms; 2.Check DiagData[7F 11 13]Within[50]ms; | L27: Pass
A28: NRC Priority Test
A29: 16 | B29: 1.General 2.DiagnosticServices | C29: Diag_0x11_Phy_016 | D29: NRC 13(min Size) > 12 | E29: High | F29: 陈亚-80025578 | G29: Based on analysis of requirements | H29: 1.Power On; | I29: 1.Send DiagBy[Physics]Data[10 03]; 2.Send DiagBy[Physics]Data[11 05]WithLen[1]; | J29: 1.Check DiagData[50 01 00 32 00 C8]Within[50]ms; 2.Check DiagData[7F 11 13]Within[50]ms; | L29: Pass
A30: 17 | B30: 1.General 2.DiagnosticServices | C30: Diag_0x11_Phy_017 | D30: NRC 12 > 7F | E30: High | F30: 陈亚-80025578 | G30: Based on analysis of requirements | H30: 1.Power On; | I30: 1.Send DiagBy[Physical]Data[10 01]; 2.Send DiagBy[Physical]Data[11 05]; | J30: 1.Check DiagData[50 01 00 32 00 C8]Within[50]ms; 2.Check DiagData[7F 11 12]Within[50]ms; | L30: Pass
A31: 18 | B31: 1.General 2.DiagnosticServices | C31: Diag_0x11_Phy_018 | D31: NRC 33 > 7F | E31: High | F31: 陈亚-80025578 | G31: Based on analysis of requirements | H31: 1.Power On; | I31: 1.Send DiagBy[Physical]Data[10 03]; 2.Send DiagBy[Physical]Data[27 01]AndCheckResp[PositiveResponse]; 3.Send Security Right KeyBy[Physical]Level[02]; 4.Send DiagBy[Physical]Data[11 01]; | J31: 1.Check DiagData[50 01 00 32 00 C8]Within[50]ms; 3.Check DiagData[67 02]Within[50]ms; 4.Check DiagData[7F 11 33]Within[50]ms; | L31: Pass
A32: 19 | B32: 1.General 2.DiagnosticServices | C32: Diag_0x11_Phy_019 | D32: NRC 22 > 33 | E32: High | F32: 陈亚-80025578 | G32: Based on analysis of requirements | H32: 1.Power On; | I32: 1.Send DiagBy[Physical]Data[10 03]; 2.Send DiagBy[Physical]Data[27 01]AndCheckResp[PositiveResponse]; 3.Send Security Right KeyBy[Physical]Level[02]; 设置车速等于10km/h 4.Set Signal[TachographVehicleSpeed]Value[10]; 5.Send DiagBy[Physical]Data[11 01]; | J32: 1.Check DiagData[50 03 00 32 00 C8]Within[50]ms; 3.Check DiagData[67 02]Within[50]ms; 5.Check DiagData[7F 11 22]Within[50]ms; | L32: Pass
A33: Voltage Condition Test (NRC 0x22)
A34: 20 | B34: 1.General 2.DiagnosticServices | C34: Diag_0x11_Phy_020 | D34: When the preset voltage condition is not met (low voltage), NRC: 0x22 is reported | E34: High | F34: 陈亚-80025578 | G34: Based on analysis of requirements | H34: 1.Power On; | I34: 1.Send DiagBy[Physical]Data[10 03]; 2.Set Voltage[8.0]V; 3.Delay[1000]ms; 4.Send DiagBy[Physical]Data[11 01]; 5.Set Voltage[12]V; | J34: 1.Check DiagData[50 03 00 32 00 C8]Within[50]ms; 4.Check DiagData[7F 11 22]Within[50]ms; | L34: Pass
A35: 21 | B35: 1.General 2.DiagnosticServices | C35: Diag_0x11_Phy_021 | D35: When the preset voltage condition is not met (high voltage), NRC: 0x22 is reported | E35: High | F35: 陈亚-80025578 | G35: Based on analysis of requirements | H35: 1.Power On; | I35: 1.Send DiagBy[Physical]Data[10 03]; 2.Set Voltage[17.0]V; 3.Delay[1000]ms; 4.Send DiagBy[Physical]Data[11 01]; 5.Set Voltage[12]V; | J35: 1.Check DiagData[50 03 00 32 00 C8]Within[50]ms; 4.Check DiagData[7F 11 22]Within[50]ms; | L35: Pass
A36: 1.7 Functional Addressing Test
A37: 22 | B37: 1.General 2.DiagnosticServices | C37: Diag_0x11_Phy_022 | D37: 0x11 Service nonsupport functional addressing subfunction 0x01 | E37: High | F37: 陈亚-80025578 | G37: Based on analysis of requirements | H37: 1.Power On; | I37: 1.Send DiagBy[Physical]Data[10 03]; 2.Send DiagBy[Function]Data[11 01]; 3.Delay[1000]ms; | J37: 1.Check DiagData[50 03 00 32 00 C8]Within[50]ms; 2.Check No_Response Within[1000]ms; | L37: Pass
A38: 23 | B38: 1.General 2.DiagnosticServices | C38: Diag_0x11_Phy_023 | D38: 0x11 Service nonsupport functional addressing subfunction 0x02 | E38: High | F38: 陈亚-80025578 | G38: Based on analysis of requirements | H38: 1.Power On; | I38: 1.Send DiagBy[Physical]Data[10 03]; 2.Send DiagBy[Function]Data[11 02]; 3.Delay[1000]ms; | J38: 1.Check DiagData[50 03 00 32 00 C8]Within[50]ms; 2.Check No_Response Within[1000]ms; | L38: Pass
A39: 24 | B39: 1.General 2.DiagnosticServices | C39: Diag_0x11_Phy_024 | D39: 0x11 Service nonsupport functional addressing subfunction 0x03 | E39: High | F39: 陈亚-80025578 | G39: Based on analysis of requirements | H39: 1.Power On; | I39: 1.Send DiagBy[Physical]Data[10 03]; 2.Send DiagBy[Function]Data[11 03]; 3.Delay[1000]ms; | J39: 1.Check DiagData[50 03 00 32 00 C8]Within[50]ms; 2.Check No_Response Within[1000]ms; | L39: Pass
A40: 3.Boot Service_Physical Addressing
...

Sheet ClearDiagnosticInformation_0x14
B1: Test Level | C1: SYS.5
A2: Sequence Number | B2: System Requirement ID | C2: Test Case | G2: Design Method | H2: Precondition | I2: Test Procedure | J2: Expected Output | K2: Actual Output | L2: Judgement Result | M2: Defect ID
C3: ID | D3: Name | E3: Priority | F3: Author
A4: 1.Application Service_Physical Addressing
A5: 1.1 Session Layer Test
A6: 1 | B6: 1.General 2.DiagnosticServices | C6: Diag_0x14_Phy_001 | D6: Default Session support 0x14 services | E6: High | F6: 陈亚-80025578 | G6: Based on analysis of requirements | H6: 1.Power On; | I6: 1.Send DiagBy[Physical]Data[10 01]; 2.Send DiagBy[Physical]Data[14 FF FF FF]; | J6: 1.Check DiagData[50 01 00 32 00 C8]Within[50]ms; 2.Check DiagData[54]Within[50]ms; | K6: Service 0x14在诊断调查表中不支持，Test case中需要回复NRC 0x11，而不是回复正向应 0x54 | L6: Fail
A7: 2 | B7: 1.General 2.DiagnosticServices | C7: Diag_0x14_Phy_002 | D7: Programming Session nonsupport 0x14 services | E7: High | F7: 陈亚-80025578 | G7: Based on analysis of requirements | H7: 1.Power On; | I7: 1.Send DiagBy[Physical]Data[10 01]; 2.Delay[1000]ms; 3.Send DiagBy[Physical]Data[10 03]; 5.Send DiagBy[Physical]Data[10 02]; 6.Send DiagBy[Physical]Data[14 FF FF FF]; | J7: 1.Check DiagData[50 01 00 32 00 C8]Within[50]ms; 2.No Check; 3.Check DiagData[50 03 00 32 00 C8]Within[50]ms; 5.Check DiagData[50 02 00 32 00 C8]Within[50]ms; 6.Check DiagData[7F 14 7F]Within[50]ms; | K7: Service 0x14在诊断调查表中不支持，Test case中需要回复NRC 0x11，而不是回复正向应 0x54 | L7: Fail
A8: 3 | B8: 1.General 2.DiagnosticServices | C8: Diag_0x14_Phy_003 | D8: Extended Session support 0x14 services | E8: High | F8: 陈亚-80025578 | G8: Based on analysis of requirements | H8: 1.Power On; | I8: 1.Send DiagBy[Physical]Data[10 03]; 2.Send DiagBy[Physical]Data[14 FF FF FF]; | J8: 1.Check DiagData[50 03 00 32 00 C8]Within[50]ms; 2.Check DiagData[54]Within[50]ms; | K8: Service 0x14在诊断调查表中不支持，Test case中需要回复NRC 0x11，而不是回复正向应 0x54 | L8: Fail
A9: 1.2 Secure Access Test
A10: 4 | B10: 1.General 2.DiagnosticServices | C10: Diag_0x14_Phy_004 | D10: Security access L1 unlock supports 0x14 services | E10: High | F10: 陈亚-80025578 | G10: Based on analysis of requirements | H10: 1.Power On; | I10: 1.Send DiagBy[Physical]Data[10 03]; 2.Send DiagBy[Physical]Data[27 01]AndCheckResp[PositiveResponse]; 3.Send Security Right KeyBy[Physical]Level[02]; 4.Send DiagBy[Physical]Data[14 FF FF FF]; | J10: 1.Check DiagData[50 03 00 32 00 C8]Within[50]ms; 3.Check DiagData[67 02]Within[50]ms; 4.Check DiagData[54]Within[50]ms; | L10: Fail
A11: 1.3 Clear DTC Function Test
A12: 6 | B12: 1.General 2.DiagnosticServices | C12: Diag_0x14_Phy_006 | D12: Failure is not recorded supports 0x14 Service | E12: High | F12: 陈亚-80025578 | G12: Based on analysis of requirements | H12: 1.Power On; | I12: 1.Send DiagBy[Physical]Data[10 03]; 2.Send DiagBy[Physical]Data[19 02 FF]; 3.Send DiagBy[Physical]Data[14 FF FF FF]; 4.Send DiagBy[Physical]Data[19 02 FF]; | J12: 1.Check DiagData[50 03 00 32 00 C8]Within[50]ms; 2.Check DiagData[59 02 09]Within[50]ms; 3.Check DiagData[54]Within[50]ms; 4.Check DiagData[59 02 09]Within[50]ms; | L12: Fail
A13: 7 | B13: 1.General 2.DiagnosticServices | C13: Diag_0x14_Phy_007 | D13: 0x14 service cleared 1 fault with status "09" | E13: High | F13: 陈亚-80025578 | G13: Based on analysis of requirements | H13: 1.Power On; | I13: 1.Send DiagBy[Physical]Data[10 03]; 2.Set Voltage[16.3]V; 3.Delay[2000]ms; 4.Send DiagBy[Physical]Data[19 02 FF]; 5.Send DiagBy[Physical]Data[14 FF FF FF]; 6.Send DiagBy[Physical]Data[19 02 FF]; 7.Set Voltage[13.5]V; 8.Delay[2000]ms; | J13: 1.Check DiagData[50 03 00 32 00 C8]Within[50]ms; 4.Check DiagData[59 02 FF XX XX XX 09]Within[50]ms; 5.Check DiagData[54]Within[50]ms; 6.Check DiagData[59 02 FF]Within[50]ms; | L13: Fail
A14: 8 | B14: 1.General 2.DiagnosticServices | C14: Diag_0x14_Phy_008 | D14: 0x14 service cleared multiple fault with status "09" | E14: High | F14: 陈亚-80025578 | G14: Based on analysis of requirements | H14: 1.Power On; | I14: 1.Send DiagBy[Physical]Data[10 03]; 2.Delay[1000]ms; 3.Send DiagBy[Physical]Data[19 02 FF]; 4.Send DiagBy[Physical]Data[14 FF FF FF]; 5.Send DiagBy[Physical]Data[19 02 FF]; | J14: 1.Check DiagData[50 03 00 32 00 C8]Within[50]ms; 3.Check DiagData[59 02 FF XX XX XX 09 XX XX XX 09]Within[50]ms; 4.Check DiagData[54]Within[50]ms; 5.Check DiagData[59 02 FF]Within[50]ms; | L14: Fail
A15: 9 | B15: 1.General 2.DiagnosticServices | C15: Diag_0x14_Phy_009 | D15: 0x14 service cleared 1 fault with status "08" | E15: High | F15: 陈亚-80025578 | G15: Based on analysis of requirements | H15: 1.Power On; | I15: 1.Send DiagBy[Physical]Data[10 03]; 2.Set Voltage[16.5]V; 3.Delay[2000]ms; 4.Set Voltage[13.5]V; 5.Delay[2000]ms; 6.Send DiagBy[Physical]Data[19 02 FF]; 7.Send DiagBy[Physical]Data[14 FF FF FF]; 8.Send DiagBy[Physical]Data[19 02 FF]; | J15: 1.Check DiagData[50 03 00 32 00 C8]Within[50]ms; 6.Check DiagData[59 02 FF XX XX XX 08]Within[50]ms; 7.Check DiagData[54]Within[50]ms; 8.Check DiagData[59 02 FF]Within[50]ms; | L15: Fail
A16: 10 | B16: 1.General 2.DiagnosticServices | C16: Diag_0x14_Phy_010 | D16: 0x14 service cleared multiple fault with status "08" | E16: High | F16: 陈亚-80025578 | G16: Based on analysis of requirements | H16: 1.Power On; | I16: 1.Send DiagBy[Physical]Data[10 03]; 2.Delay[1000]ms; 3.Send DiagBy[Physical]Data[19 02 FF]; 4.Send DiagBy[Physical]Data[14 FF FF FF]; 5.Send DiagBy[Physical]Data[19 02 FF]; | J16: 1.Check DiagData[50 03 00 32 00 C8]Within[50]ms; 3.Check DiagData[59 02 FF XX XX XX 08 XX XX XX 08]Within[50]ms; 4.Check DiagData[54]Within[50]ms; 5.Check DiagData[59 02 FF]Within[50]ms; | L16: Fail
A17: 1.4 Incorrect Diagnostic Command Test
A18: 11 | B18: 1.General 2.DiagnosticServices | C18: Diag_0x14_Phy_011 | D18: Valid SF_DL=4, invalid SF_DL > 4, and those with invalid equivalence class SF_DL=5 | E18: Low | F18: 陈亚-80025578 | G18: Based on analysis of requirements | H18: 1.Power On; | I18: 1.Send DiagBy[Physical]Data[10 03]; 2.Send DiagBy[Physical]Data[14 FF FF FF]WithLen[5]; | J18: 1.Check DiagData[50 03 00 32 00 C8]Within[50]ms; 2.Check DiagData[7F 14 13]Within[50]ms; | L18: Fail
A19: 12 | B19: 1.General 2.DiagnosticServices | C19: Diag_0x14_Phy_012 | D19: Valid SF_DL=4, invalid SF_DL < 4, and those with invalid equivalence class SF_DL=3 | E19: Low | F19: 陈亚-80025578 | G19: Based on analysis of requirements | H19: 1.Power On; | I19: 1.Send DiagBy[Physical]Data[10 03]; 2.Send DiagBy[Physical]Data[14 FF FF FF]WithLen[3]; | J19: 1.Check DiagData[50 03 00 32 00 C8]Within[50]ms; 2.Check DiagData[7F 14 13]Within[50]ms; | L19: Fail
A20: 1.5 NRC Priority Test
A21: 13 | B21: 1.General 2.DiagnosticServices | C21: Diag_0x14_Phy_013 | D21: NRC 13>31 | E21: High | F21: 陈亚-80025578 | G21: Based on analysis of requirements | H21: 1.Power On; | I21: 1.Send DiagBy[Physical]Data[10 03]; 2.Send DiagBy[Physical]Data[14 00 FF FF]WithLen[5]; | J21: 1.Check DiagData[50 03 00 32 00 C8]Within[50]ms; 2.Check DiagData[7F 14 13]Within[50]ms; | L21: Fail
A22: 2.Application Service_Functional Addressing
A23: 2.1 Session Layer Test
A24: 14 | B24: 1.General 2.DiagnosticServices | C24: Diag_0x14_Fun_001 | D24: Default Session support 0x14 services | E24: High | F24: 陈亚-80025578 | G24: Based on analysis of requirements | H24: 1.Power On; | I24: 1.Send DiagBy[Physical]Data[10 01]; 2.Send DiagBy[Function]Data[14 FF FF FF]; | J24: 1.Check DiagData[50 01 00 32 00 C8]Within[50]ms; 2.Check No_Response Within[1000]ms; | L24: Fail
A25: 15 | B25: 1.General 2.DiagnosticServices | C25: Diag_0x14_Fun_002 | D25: Programming Session nonsupport 0x14 services | E25: High | F25: 陈亚-80025578 | G25: Based on analysis of requirements | H25: 1.Power On; | I25: 1.Send DiagBy[Physical]Data[10 01]; 2.Delay[1000]ms; 3.Send DiagBy[Physical]Data[10 03]; 5.Send DiagBy[Physical]Data[10 02]; 6.Send DiagBy[Function]Data[14 FF FF FF]; | J25: 1.Check DiagData[50 01 00 32 00 C8]Within[50]ms; 2.No Check; 3.Check DiagData[50 03 00 32 00 C8]Within[50]ms; 5.Check DiagData[50 02 00 32 00 C8]Within[50]ms; 6.Check No_Response Within[1000]ms; | L25: Fail
A26: 16 | B26: 1.General 2.DiagnosticServices | C26: Diag_0x14_Fun_003 | D26: Extended Session support 0x14 services | E26: High | F26: 陈亚-80025578 | G26: Based on analysis of requirements | H26: 1.Power On; | I26: 1.Send DiagBy[Physical]Data[10 03]; 2.Send DiagBy[Function]Data[14 FF FF FF]; | J26: 1.Check DiagData[50 03 00 32 00 C8]Within[50]ms; 2.Check No_Response Within[1000]ms; | L26: Fail
A27: 2.2 Secure Access Test
A28: 17 | B28: 1.General 2.DiagnosticServices | C28: Diag_0x14_Fun_004 | D28: Security access L1 unlock supports 0x14 services | E28: High | F28: 陈亚-80025578 | G28: Based on analysis of requirements | H28: 1.Power On; | I28: 1.Send DiagBy[Physical]Data[10 03]; 2.Send DiagBy[Physical]Data[27 01]AndCheckResp[PositiveResponse]; 3.Send Security Right KeyBy[Physical]Level[02]; 4.Send DiagBy[Function]Data[14 FF FF FF]; | J28: 1.Check DiagData[50 03 00 32 00 C8]Within[50]ms; 3.Check DiagData[67 02]Within[50]ms; 4.Check No_Response Within[1000]ms; | L28: Fail
A29: 18 | B29: 1.General 2.DiagnosticServices | C29: Diag_0x14_Fun_005 | D29: Security access L2 unlock supports 0x14 services | E29: High | F29: 陈亚-80025578 | G29: Based on analysis of requirements | H29: 1.Power On; | I29: 1.Send DiagBy[Physical]Data[10 03]; 2.Send DiagBy[Physical]Data[27 03]AndCheckResp[PositiveResponse]; 3.Send Security Right KeyBy[Physical]Level[04]; 4.Send DiagBy[Function]Data[14 FF FF FF]; | J29: 1.Check DiagData[50 03 00 32 00 C8]Within[50]ms; 3.Check DiagData[67 04]Within[50]ms; 4.Check No_Response Within[1000]ms; | L29: Fail
A30: 2.3 Clear DTC Function Test
A31: 19 | B31: 1.General 2.DiagnosticServices | C31: Diag_0x14_Fun_006 | D31: Failure is not recorded supports 0x14 Service | E31: High | F31: 陈亚-80025578 | G31: Based on analysis of requirements | H31: 1.Power On; | I31: 1.Send DiagBy[Physical]Data[10 03]; 2.Send DiagBy[Physical]Data[19 02 FF]; 3.Send DiagBy[Function]Data[14 FF FF FF]; 4.Send DiagBy[Physical]Data[19 02 FF]; | J31: 1.Check DiagData[50 03 00 32 00 C8]Within[50]ms; 2.Check DiagData[59 02 FF]Within[50]ms; 3.Check No_Response Within[1000]ms; 4.Check DiagData[59 02 FF]Within[50]ms; | L31: Fail
A32: 20 | B32: 1.General 2.DiagnosticServices | C32: Diag_0x14_Fun_007 | D32: 0x14 service cleared 1 fault with status "09" | E32: High | F32: 陈亚-80025578 | G32: Based on analysis of requirements | H32: 1.Power On; | I32: 1.Send DiagBy[Physical]Data[10 03]; 2.Set Voltage[16.3]V; 3.Delay[2000]ms; 4.Send DiagBy[Physical]Data[19 02 FF]; 5.Send DiagBy[Function]Data[14 FF FF FF]; 6.Send DiagBy[Physical]Data[19 02 FF]; 7.Set Voltage[13.5]V; 8.Delay[2000]ms; | J32: 1.Check DiagData[50 03 00 32 00 C8]Within[50]ms; 4.Check DiagData[59 02 FF XX XX XX 09]Within[50]ms; 5.Check No_Response Within[1000]ms; 6.Check DiagData[59 02 FF]Within[50]ms; | L32: Fail
A33: 21 | B33: 1.General 2.DiagnosticServices | C33: Diag_0x14_Fun_008 | D33: 0x14 service cleared multiple fault with status "09" | E33: High | F33: 陈亚-80025578 | G33: Based on analysis of requirements | H33: 1.Power On; | I33: 1.Send DiagBy[Physical]Data[10 03]; 2.Delay[1000]ms; 3.Send DiagBy[Physical]Data[19 02 FF]; 4.Send DiagBy[Function]Data[14 FF FF FF]; 5.Send DiagBy[Physical]Data[19 02 FF]; | J33: 1.Check DiagData[50 03 00 32 00 C8]Within[50]ms; 3.Check DiagData[59 02 FF XX XX XX 09 XX XX XX 09]Within[50]ms; 4.Check No_Response Within[1000]ms; 5.Check DiagData[59 02 FF]Within[50]ms; | L33: Fail
A34: 22 | B34: 1.General 2.DiagnosticServices | C34: Diag_0x14_Fun_009 | D34: 0x14 service cleared 1 fault with status "08" | E34: High | F34: 陈亚-80025578 | G34: Based on analysis of requirements | H34: 1.Power On; | I34: 1.Send DiagBy[Physical]Data[10 03]; 2.Set Voltage[16.5]V; 3.Delay[2000]ms; 4.Set Voltage[13.5]V; 5.Delay[2000]ms; 6.Send DiagBy[Physical]Data[19 02 FF]; 7.Send DiagBy[Function]Data[14 FF FF FF]; 8.Send DiagBy[Physical]Data[19 02 FF]; | J34: 1.Check DiagData[50 03 00 32 00 C8]Within[50]ms; 6.Check DiagData[59 02 FF XX XX XX 08]Within[50]ms; 7.Check No_Response Within[1000]ms; 8.Check DiagData[59 02 FF]Within[50]ms; | L34: Fail
A35: 23 | B35: 1.General 2.DiagnosticServices | C35: Diag_0x14_Fun_010 | D35: 0x14 service cleared multiple fault with status "08" | E35: High | F35: 陈亚-80025578 | G35: Based on analysis of requirements | H35: 1.Power On; | I35: 1.Send DiagBy[Physical]Data[10 03]; 2.Delay[1000]ms; 3.Send DiagBy[Physical]Data[19 02 FF]; 4.Send DiagBy[Function]Data[14 FF FF FF]; 5.Send DiagBy[Physical]Data[19 02 FF]; | J35: 1.Check DiagData[50 03 00 32 00 C8]Within[50]ms; 3.Check DiagData[59 02 FF XX XX XX 08 XX XX XX 08]Within[50]ms; 4.Check No_Response Within[1000]ms; 5.Check DiagData[59 02 FF]Within[50]ms; | L35: Fail
A36: 2.4 Incorrect Diagnostic Command Test
A37: 24 | B37: 1.General 2.DiagnosticServices | C37: Diag_0x14_Fun_011 | D37: Valid SF_DL=4, invalid SF_DL > 4, and those with invalid equivalence class SF_DL=5 | E37: Low | F37: 陈亚-80025578 | G37: Based on analysis of requirements | H37: 1.Power On; | I37: 1.Send DiagBy[Physical]Data[10 03]; 2.Send DiagBy[Function]Data[14 FF FF FF]WithLen[5]; | J37: 1.Check DiagData[50 03 00 32 00 C8]Within[50]ms; 2.Check No_Response Within[1000]ms; | L37: Fail
A38: 25 | B38: 1.General 2.DiagnosticServices | C38: Diag_0x14_Fun_012 | D38: Valid SF_DL=4, invalid SF_DL < 4, and those with invalid equivalence class SF_DL=3 | E38: Low | F38: 陈亚-80025578 | G38: Based on analysis of requirements | H38: 1.Power On; | I38: 1.Send DiagBy[Physical]Data[10 03]; 2.Send DiagBy[Function]Data[14 FF FF FF]WithLen[3]; | J38: 1.Check DiagData[50 03 00 32 00 C8]Within[50]ms; 2.Check No_Response Within[1000]ms; | L38: Fail
A39: 2.5 NRC Priority Test
A40: 26 | B40: 1.General 2.DiagnosticServices | C40: Diag_0x14_Fun_013 | D40: NRC 13>31 | E40: High | F40: 陈亚-80025578 | G40: Based on analysis of requirements | H40: 1.Power On; | I40: 1.Send DiagBy[Physical]Data[10 03]; 2.Send DiagBy[Function]Data[14 00 FF FF]WithLen[5]; | J40: 1.Check DiagData[50 03 00 32 00 C8]Within[50]ms; 2.Check No_Response Within[1000]ms; | L40: Fail
...

Sheet ClearDiagnosticIn_0x14_confirm
B1: Test Level | C1: SYS.5
A2: Sequence Number | B2: System Requirement ID | C2: Test Case | G2: Design Method | H2: Precondition | I2: Test Procedure | J2: Expected Output | K2: Actual Output | L2: Judgement Result | M2: Defect ID
C3: ID | D3: Name | E3: Priority | F3: Author
A4: 1.Application Service_Physical Addressing
A5: 1.1 Session Layer Test
A6: 1 | B6: 1.General 2.DiagnosticServices | C6: Diag_0x14_Phy_001 | D6: Default Session support 0x14 services | E6: High | F6: 陈亚-80025578 | G6: Based on analysis of requirements | H6: 1.Power On; | I6: 1.Send DiagBy[Physical]Data[10 01]; 2.Send DiagBy[Physical]Data[14 FF FF FF]; | J6: 1.Check DiagData[50 01 00 32 00 C8]Within[50]ms; 2.Check DiagData[7F 14 11]Within[50]ms;
A7: 2 | B7: 1.General 2.DiagnosticServices | C7: Diag_0x14_Phy_002 | D7: Programming Session nonsupport 0x14 services | E7: High | F7: 陈亚-80025578 | G7: Based on analysis of requirements | H7: 1.Power On; | I7: 1.Send DiagBy[Physical]Data[10 01]; 2.Delay[1000]ms; 3.Send DiagBy[Physical]Data[10 03]; 4.Send DiagBy[Physical]Data[10 02]; 5.Send DiagBy[Physical]Data[14 FF FF FF]; | J7: 1.Check DiagData[50 01 00 32 00 C8]Within[50]ms; 3.Check DiagData[50 03 00 32 00 C8]Within[50]ms; 4.Check DiagData[50 02 00 32 00 C8]Within[50]ms; 5.Check DiagData[7F 14 11]Within[50]ms;
A8: 3 | B8: 1.General 2.DiagnosticServices | C8: Diag_0x14_Phy_003 | D8: Extended Session support 0x14 services | E8: High | F8: 陈亚-80025578 | G8: Based on analysis of requirements | H8: 1.Power On; | I8: 1.Send DiagBy[Physical]Data[10 03]; 2.Send DiagBy[Physical]Data[14 FF FF FF]; | J8: 1.Check DiagData[50 03 00 32 00 C8]Within[50]ms; 2.Check DiagData[7F 14 11]Within[50]ms;

Sheet ReadDTCInformation_0x19
B1: Test Level | C1: SYS.5
A2: Sequence Number | B2: System Requirement ID | C2: Test Case | G2: Design Method | H2: Precondition | I2: Test Procedure | J2: Expected Output | K2: Actual Output | L2: Judgement Result | M2: Defect ID
C3: ID | D3: Name | E3: Priority | F3: Author
A4: 1 | B4: 1.General 2.DiagnosticServices | C4: Diag_0x19_Phy_001 | D4: Default Session support 0x19 services | E4: High | F4: 陈亚-80025578 | G4: Based on analysis of requirements | H4: 1.Power On; | I4: 1.Send DiagBy[Physical]Data[10 01]; 2.Send DiagBy[Physical]Data[19 01]; | J4: 1.Check DiagData[50 01 00 32 00 C8]Within[50]ms; 2.Check DiagData[7F 19 11]Within[50]ms; | L4: Block
A5: 2 | B5: 1.General 2.DiagnosticServices | C5: Diag_0x19_Phy_002 | D5: Programming Session nonsupport 0x19 services | E5: High | F5: 陈亚-80025578 | G5: Based on analysis of requirements | H5: 1.Power On; | I5: 1.Send DiagBy[Physical]Data[10 01]; 2.Delay[1000]ms; 3.Send DiagBy[Physical]Data[10 03]; 4.Send DiagBy[Physical]Data[10 02]; 5.Send DiagBy[Physical]Data[19 01]; | J5: 1.Check DiagData[50 01 00 32 00 C8]Within[50]ms; 3.Check DiagData[50 03 00 32 00 C8]Within[50]ms; 4.Check DiagData[50 02 00 32 00 C8]Within[50]ms; 5.Check DiagData[7F 19 11]Within[50]ms; | L5: Block
A6: 3 | B6: 1.General 2.DiagnosticServices | C6: Diag_0x19_Phy_003 | D6: Extended Session support 0x19 services | E6: High | F6: 陈亚-80025578 | G6: Based on analysis of requirements | H6: 1.Power On; | I6: 1.Send DiagBy[Physical]Data[10 03]; 2.Send DiagBy[Physical]Data[19 01]; | J6: 1.Check DiagData[50 03 00 32 00 C8]Within[50]ms; 2.Check DiagData[7F 19 11]Within[50]ms; | L6: Block

Sheet ReadDataByIdentifier_0x22
B1: Test Level | C1: SYS.5
A2: Sequence Number | B2: System Requirement ID | C2: Test Case | G2: Design Method | H2: Precondition | I2: Test Procedure | J2: Expected Output | K2: Actual Output | L2: Judgement Result | M2: Defect ID
C3: ID | D3: Name | E3: Priority | F3: Author
A4: Service 0x22 ReadDataByIdentifier 测试用例 ---SV/HU-L
A5: 1.1 Session Layer Test (APP)
A6: 1 | B6: 1.General 2.DiagnosticServices | C6: Diag_0x22_Phy_001 | D6: Default Session supports reading DID: 0xF6C3 PositiveCase-$22 | E6: High | F6: 陈亚-80025578 | G6: Based on analysis of requirements | H6: 1.Power On; | I6: 1.Send DiagBy[Physical]Data[10 01]; 2.Send DiagBy[Physical]Data[22 F6 C3]; | J6: 1.Check DiagData[50 01 00 32 00 C8]Within[50]ms; 2.Check DiagData[62 F6 C3 xx xx xx xx xx]Within[50]ms; | K6: 1.测试过程与检验结果中缺少编号 2.测试过程不应该出现check结果 | L6: Fail
A7: 2 | B7: 1.General 2.DiagnosticServices | C7: Diag_0x22_Phy_002 | D7: Default Session supports reading DID: 0xF6C4 PositiveCase-$22 | E7: High | F7: 陈亚-80025578 | G7: Based on analysis of requirements | H7: 1.Power On; | I7: 1.Send DiagBy[Physical]Data[10 01]; 2.Send DiagBy[Physical]Data[22 F6 C4]; | J7: 1.Check DiagData[50 01 00 32 00 C8]Within[50]ms; SV软件编码： 2.Check DiagData[62 F6 C4 00 54 00 13 2B 8F 00 00 00]Within[50]ms; | L7: Fail
A8: 3 | B8: 1.General 2.DiagnosticServices | C8: Diag_0x22_Phy_003 | D8: Default Session supports reading DID: 0xF6C5 PositiveCase-$22 | E8: High | F8: 陈亚-80025578 | G8: Based on analysis of requirements | H8: 1.Power On; | I8: 1.Send DiagBy[Physical]Data[10 01]; 2.Send DiagBy[Physical]Data[22 F6 C5]; | J8: 1.Check DiagData[50 01 00 32 00 C8]Within[50]ms; 版本号：0.00.01 2.Check DiagData[62 F6 C5 00 00 00 00 00 00]Within[50]ms; | L8: Fail
A9: 4 | B9: 1.General 2.DiagnosticServices | C9: Diag_0x22_Phy_004 | D9: Default Session supports reading DID: 0xF6C0 PositiveCase-$22 | E9: High | F9: 陈亚-80025578 | G9: Based on analysis of requirements | H9: 1.Power On; | I9: 1.Send DiagBy[Physical]Data[10 01]; 2.Send DiagBy[Physical]Data[22 F6 C0]; | J9: 1.Check DiagData[50 01 00 32 00 C8]Within[50]ms; 2.Check DiagData[62 F6 C0 xx xx xx xx xx xx xx xx xx]Within[50]ms; | L9: Fail
A10: 1 | B10: 1.General 2.DiagnosticServices | C10: Diag_0x22_Phy_005 | D10: Extended Session supports reading DID: 0xF6C3 PositiveCase-$22 | E10: High | F10: 陈亚-80025578 | G10: Based on analysis of requirements | H10: 1.Power On; | I10: 1.Send DiagBy[Physical]Data[10 03]; 2.Send DiagBy[Physical]Data[22 F6 C3]; | J10: 1.Check DiagData[50 03 00 32 00 C8]Within[50]ms; 2.Check DiagData[62 F6 C3 xx xx xx xx xx]Within[50]ms; | K10: 1.测试过程与检验结果中缺少编号 2.测试过程不应该出现check结果 | L10: Fail
A11: 2 | B11: 1.General 2.DiagnosticServices | C11: Diag_0x22_Phy_006 | D11: Extended Session supports reading DID: 0xF6C4 PositiveCase-$22 | E11: High | F11: 陈亚-80025578 | G11: Based on analysis of requirements | H11: 1.Power On; | I11: 1.Send DiagBy[Physical]Data[10 03]; 2.Send DiagBy[Physical]Data[22 F6 C4]; | J11: 1.Check DiagData[50 03 00 32 00 C8]Within[50]ms; SV软件编码： 2.Check DiagData[62 F6 C4 00 54 00 13 2B 8F 00 00 00]Within[50]ms; | L11: Fail
A12: 3 | B12: 1.General 2.DiagnosticServices | C12: Diag_0x22_Phy_007 | D12: Extended Session supports reading DID: 0xF6C5 PositiveCase-$22 | E12: High | F12: 陈亚-80025578 | G12: Based on analysis of requirements | H12: 1.Power On; | I12: 1.Send DiagBy[Physical]Data[10 03]; 2.Send DiagBy[Physical]Data[22 F6 C5]; | J12: 1.Check DiagData[50 03 00 32 00 C8]Within[50]ms; 版本号：0.00.01 2.Check DiagData[62 F6 C5 00 00 00 00 00 00]Within[50]ms; | L12: Fail
A13: 4 | B13: 1.General 2.DiagnosticServices | C13: Diag_0x22_Phy_008 | D13: Extended Session supports reading DID: 0xF6C0 PositiveCase-$22 | E13: High | F13: 陈亚-80025578 | G13: Based on analysis of requirements | H13: 1.Power On; | I13: 1.Send DiagBy[Physical]Data[10 03]; 2.Send DiagBy[Physical]Data[22 F6 C0]; | J13: 1.Check DiagData[50 03 00 32 00 C8]Within[50]ms; 2.Check DiagData[62 F6 C0 xx xx xx xx xx xx xx xx xx]Within[50]ms; | L13: Fail
A14: 1 | B14: 1.General 2.DiagnosticServices | C14: Diag_0x22_Phy_009 | D14: Programme Session supports reading DID: 0xF6C3 PositiveCase-$22 | E14: High | F14: 陈亚-80025578 | G14: Based on analysis of requirements | H14: 1.Power On; | I14: 1.Send DiagBy[Physical]Data[10 03]; 2.Send DiagBy[Physical]Data[10 02]; 3.Send DiagBy[Physical]Data[22 F6 C3]; | J14: 1.Check DiagData[50 03 00 32 00 C8]Within[50]ms; 2.Check DiagData[50 02 00 32 00 C8]Within[50]ms; 3.Check DiagData[62 F6 C3 xx xx xx xx xx]Within[50]ms; | K14: 1.测试过程与检验结果中缺少编号 2.测试过程不应该出现check结果 | L14: Fail
A15: 2 | B15: 1.General 2.DiagnosticServices | C15: Diag_0x22_Phy_010 | D15: Programme Session supports reading DID: 0xF6C4 PositiveCase-$22 | E15: High | F15: 陈亚-80025578 | G15: Based on analysis of requirements | H15: 1.Power On; | I15: 1.Send DiagBy[Physical]Data[10 03]; 2.Send DiagBy[Physical]Data[10 02]; 3.Send DiagBy[Physical]Data[22 F6 C4]; | J15: 1.Check DiagData[50 03 00 32 00 C8]Within[50]ms; 2.Check DiagData[50 02 00 32 00 C8]Within[50]ms; SV软件编码： 3.Check DiagData[62 F6 C4 00 54 00 13 2B 8F 00 00 00]Within[50]ms; | L15: Fail
A16: 3 | B16: 1.General 2.DiagnosticServices | C16: Diag_0x22_Phy_011 | D16: Programme Session supports reading DID: 0xF6C5 PositiveCase-$22 | E16: High | F16: 陈亚-80025578 | G16: Based on analysis of requirements | H16: 1.Power On; | I16: 1.Send DiagBy[Physical]Data[10 03]; 2.Send DiagBy[Physical]Data[10 02]; 3.Send DiagBy[Physical]Data[22 F6 C5]; | J16: 1.Check DiagData[50 03 00 32 00 C8]Within[50]ms; 2.Check DiagData[50 02 00 32 00 C8]Within[50]ms; 版本号：0.00.01 3.Check DiagData[62 F6 C5 00 00 00 00 00 00]Within[50]ms; | L16: Fail
A17: 4 | B17: 1.General 2.DiagnosticServices | C17: Diag_0x22_Phy_012 | D17: Programme Session supports reading DID: 0xF6C0 PositiveCase-$22 | E17: High | F17: 陈亚-80025578 | G17: Based on analysis of requirements | H17: 1.Power On; | I17: 1.Send DiagBy[Physical]Data[10 03]; 2.Send DiagBy[Physical]Data[10 02]; 3.Send DiagBy[Physical]Data[22 F6 C0]; | J17: 1.Check DiagData[50 03 00 32 00 C8]Within[50]ms; 2.Check DiagData[50 02 00 32 00 C8]Within[50]ms; 3.Check DiagData[62 F6 C0 xx xx xx xx xx xx xx xx xx]Within[50]ms; | L17: Fail
A18: 1.2 Session Layer Test (Function)
A19: 1 | B19: 1.General 2.DiagnosticServices | C19: Diag_0x22_Fun_013 | D19: Default Session supports reading DID: 0xF6C3 PositiveCase-$22 | E19: High | F19: 陈亚-80025578 | G19: Based on analysis of requirements | H19: 1.Power On; | I19: 1.Send DiagBy[Physical]Data[10 01]; 2.Send DiagBy[Functional]Data[22 F6 C3]; | J19: 1.Check DiagData[50 01 00 32 00 C8]Within[50]ms; 2.Check No_ResponseWithin[1000]ms; | K19: 1.测试过程与检验结果中缺少编号 2.测试过程不应该出现check结果 | L19: Fail
A20: 2 | B20: 1.General 2.DiagnosticServices | C20: Diag_0x22_Fun_014 | D20: Default Session supports reading DID: 0xF6C4 PositiveCase-$22 | E20: High | F20: 陈亚-80025578 | G20: Based on analysis of requirements | H20: 1.Power On; | I20: 1.Send DiagBy[Physical]Data[10 01]; 2.Send DiagBy[Functional]Data[22 F6 C4]; | J20: 1.Check DiagData[50 01 00 32 00 C8]Within[50]ms; SV软件编码： 2.Check No_ResponseWithin[1000]ms; | L20: Fail
A21: 3 | B21: 1.General 2.DiagnosticServices | C21: Diag_0x22_Fun_015 | D21: Default Session supports reading DID: 0xF6C5 PositiveCase-$22 | E21: High | F21: 陈亚-80025578 | G21: Based on analysis of requirements | H21: 1.Power On; | I21: 1.Send DiagBy[Physical]Data[10 01]; 2.Send DiagBy[Functional]Data[22 F6 C5]; | J21: 1.Check DiagData[50 01 00 32 00 C8]Within[50]ms; 版本号：0.00.01 2.Check No_ResponseWithin[1000]ms; | L21: Fail
A22: 4 | B22: 1.General 2.DiagnosticServices | C22: Diag_0x22_Fun_016 | D22: Default Session supports reading DID: 0xF6C0 PositiveCase-$22 | E22: High | F22: 陈亚-80025578 | G22: Based on analysis of requirements | H22: 1.Power On; | I22: 1.Send DiagBy[Physical]Data[10 01]; 2.Send DiagBy[Functional]Data[22 F6 C0]; | J22: 1.Check DiagData[50 01 00 32 00 C8]Within[50]ms; 2.Check No_ResponseWithin[1000]ms; | L22: Fail
A23: 1 | B23: 1.General 2.DiagnosticServices | C23: Diag_0x22_Fun_017 | D23: Extended Session supports reading DID: 0xF6C3 PositiveCase-$22 | E23: High | F23: 陈亚-80025578 | G23: Based on analysis of requirements | H23: 1.Power On; | I23: 1.Send DiagBy[Physical]Data[10 03]; 2.Send DiagBy[Functional]Data[22 F6 C3]; | J23: 1.Check DiagData[50 03 00 32 00 C8]Within[50]ms; 2.Check No_ResponseWithin[1000]ms; | K23: 1.测试过程与检验结果中缺少编号 2.测试过程不应该出现check结果 | L23: Fail
A24: 2 | B24: 1.General 2.DiagnosticServices | C24: Diag_0x22_Fun_018 | D24: Extended Session supports reading DID: 0xF6C4 PositiveCase-$22 | E24: High | F24: 陈亚-80025578 | G24: Based on analysis of requirements | H24: 1.Power On; | I24: 1.Send DiagBy[Physical]Data[10 03]; 2.Send DiagBy[Functional]Data[22 F6 C4]; | J24: 1.Check DiagData[50 03 00 32 00 C8]Within[50]ms; SV软件编码： 2.Check No_ResponseWithin[1000]ms; | L24: Fail
A25: 3 | B25: 1.General 2.DiagnosticServices | C25: Diag_0x22_Fun_019 | D25: Extended Session supports reading DID: 0xF6C5 PositiveCase-$22 | E25: High | F25: 陈亚-80025578 | G25: Based on analysis of requirements | H25: 1.Power On; | I25: 1.Send DiagBy[Physical]Data[10 03]; 2.Send DiagBy[Functional]Data[22 F6 C5]; | J25: 1.Check DiagData[50 03 00 32 00 C8]Within[50]ms; 版本号：0.00.01 2.Check No_ResponseWithin[1000]ms; | L25: Fail
A26: 4 | B26: 1.General 2.DiagnosticServices | C26: Diag_0x22_Fun_020 | D26: Extended Session supports reading DID: 0xF6C0 PositiveCase-$22 | E26: High | F26: 陈亚-80025578 | G26: Based on analysis of requirements | H26: 1.Power On; | I26: 1.Send DiagBy[Physical]Data[10 03]; 2.Send DiagBy[Functional]Data[22 F6 C0]; | J26: 1.Check DiagData[50 03 00 32 00 C8]Within[50]ms; 2.Check No_ResponseWithin[1000]ms; | L26: Fail
A27: 1 | B27: 1.General 2.DiagnosticServices | C27: Diag_0x22_Fun_021 | D27: Programme Session supports reading DID: 0xF6C3 PositiveCase-$22 | E27: High | F27: 陈亚-80025578 | G27: Based on analysis of requirements | H27: 1.Power On; | I27: 1.Send DiagBy[Physical]Data[10 03]; 2.Send DiagBy[Physical]Data[10 02]; 3.Send DiagBy[Functional]Data[22 F6 C3]; | J27: 1.Check DiagData[50 03 00 32 00 C8]Within[50]ms; 2.Check DiagData[50 02 00 32 00 C8]Within[50]ms; 3.Check No_ResponseWithin[1000]ms; | K27: 1.测试过程与检验结果中缺少编号 2.测试过程不应该出现check结果 | L27: Fail
A28: 2 | B28: 1.General 2.DiagnosticServices | C28: Diag_0x22_Fun_022 | D28: Programme Session supports reading DID: 0xF6C4 PositiveCase-$22 | E28: High | F28: 陈亚-80025578 | G28: Based on analysis of requirements | H28: 1.Power On; | I28: 1.Send DiagBy[Physical]Data[10 03]; 2.Send DiagBy[Physical]Data[10 02]; 3.Send DiagBy[Functional]Data[22 F6 C4]; | J28: 1.Check DiagData[50 03 00 32 00 C8]Within[50]ms; 2.Check DiagData[50 02 00 32 00 C8]Within[50]ms; SV软件编码： 3.Check No_ResponseWithin[1000]ms; | L28: Fail
A29: 3 | B29: 1.General 2.DiagnosticServices | C29: Diag_0x22_Fun_023 | D29: Programme Session supports reading DID: 0xF6C5 PositiveCase-$22 | E29: High | F29: 陈亚-80025578 | G29: Based on analysis of requirements | H29: 1.Power On; | I29: 1.Send DiagBy[Physical]Data[10 03]; 2.Send DiagBy[Physical]Data[10 02]; 3.Send DiagBy[Functional]Data[22 F6 C5]; | J29: 1.Check DiagData[50 03 00 32 00 C8]Within[50]ms; 2.Check DiagData[50 02 00 32 00 C8]Within[50]ms; 版本号：0.00.01 3.Check No_ResponseWithin[1000]ms; | L29: Fail
A30: 4 | B30: 1.General 2.DiagnosticServices | C30: Diag_0x22_Fun_024 | D30: Programme Session supports reading DID: 0xF6C0 PositiveCase-$22 | E30: High | F30: 陈亚-80025578 | G30: Based on analysis of requirements | H30: 1.Power On; | I30: 1.Send DiagBy[Physical]Data[10 03]; 2.Send DiagBy[Physical]Data[10 02]; 3.Send DiagBy[Functional]Data[22 F6 C0]; | J30: 1.Check DiagData[50 03 00 32 00 C8]Within[50]ms; 2.Check DiagData[50 02 00 32 00 C8]Within[50]ms; 3.Check No_ResponseWithin[1000]ms; | L30: Fail
A31: 1.3 NRC test
B32: 1.General 2.DiagnosticServices | C32: Diag_0x22_Fun_025 | D32: Programing Session NRC 0x31 | E32: Low | F32: 陈亚-80025578 | G32: Based on analysis of requirements | H32: 1.Power On | I32: 1.Send DiagBy[Physical]Data[10 03 ]; 2.Send DiagBy[Physical]Data[22 F6 C0 F1]; | J32: 1.Check DiagData[50 03 00 32 01 F4]Within[50]ms; 2.Check DiagData[7F 22 31]Within[50]ms; | L32: Fail
B33: 1.General 2.DiagnosticServices | C33: Diag_0x22_Fun_026 | D33: Programing Session NRC 0x13>0x31 | E33: Low | F33: 陈亚-80025578 | G33: Based on analysis of requirements | H33: 1.Power On | I33: 1.Send DiagBy[Physical]Data[10 03 ]; 2.Send DiagBy[Physical]Data[22 F6 C0]WithLen[3]; | J33: 1.Check DiagData[50 03 00 32 01 F4]Within[50]ms; 2.Check DiagData[7F 22 13]Within[50]ms; | L33: Fail
A34: 1.3 Boot Session Layer Test
A35: 1 | B35: 1.General 2.DiagnosticServices | C35: Diag_0x22_Phy_027 | D35: Default Session supports reading DID: 0xF6C3 PositiveCase-$22 | E35: High | F35: 陈亚-80025578 | G35: Based on analysis of requirements | H35: 1.Power On; | I35: 1.Send DiagBy[Physical]Data[10 01]; 2.Send DiagBy[Physical]Data[22 F6 C3]; | J35: 1.Check DiagData[50 01 00 32 00 C8]Within[50]ms; 2.Check DiagData[62 F6 C3 xx xx xx xx xx]Within[50]ms; | K35: 1.测试过程与检验结果中缺少编号 2.测试过程不应该出现check结果 | L35: Fail
A36: 2 | B36: 1.General 2.DiagnosticServices | C36: Diag_0x22_Phy_028 | D36: Default Session supports reading DID: 0xF6C4 PositiveCase-$22 | E36: High | F36: 陈亚-80025578 | G36: Based on analysis of requirements | H36: 1.Power On; | I36: 1.Send DiagBy[Physical]Data[10 01]; 2.Send DiagBy[Physical]Data[22 F6 C4]; | J36: 1.Check DiagData[50 01 00 32 00 C8]Within[50]ms; SV软件编码： 2.Check DiagData[62 F6 C4 00 54 00 13 2B 8F 00 00 00]Within[50]ms; | L36: Fail
A37: 3 | B37: 1.General 2.DiagnosticServices | C37: Diag_0x22_Phy_029 | D37: Default Session supports reading DID: 0xF6C5 PositiveCase-$22 | E37: High | F37: 陈亚-80025578 | G37: Based on analysis of requirements | H37: 1.Power On; | I37: 1.Send DiagBy[Physical]Data[10 01]; 2.Send DiagBy[Physical]Data[22 F6 C5]; | J37: 1.Check DiagData[50 01 00 32 00 C8]Within[50]ms; 版本号：0.00.01 2.Check DiagData[62 F6 C5 00 00 00 00 00 00]Within[50]ms; | L37: Fail
