Workbook

Sheet DiagnosticSessionControl_0x10
B1: Test Level | C1: SYS.5
A2: Sequence Number | B2: System Requirement ID | C2: Test Case | G2: Design Method | H2: Precondition | I2: Test Procedure | J2: Expected Output | K2: Actual Output | L2: Judgement Result | M2: Defect ID
C3: ID | D3: Name | E3: Priority | F3: Author
A4: 1.Application Service_Physical Addressing
A5: 1.1 Session Layer Test
A6: 1 | B6: 1.General 2.DiagnosticServices | C6: Diag_0x10_Phy_001 | D6: Service 0x10 Default To Default | E6: High | F6: 陈亚-80025578 | G6: Based on analysis of requirements | H6: 1.Power On; | I6: 1.Send DiagBy[Physical]Data[10 01]; 2.Send DiagBy[Physical]Data[10 01]; | J6: 1.Check DiagData[50 01 00 32 00 C8]Within[50]ms; 2.Check DiagData[50 01 00 32 00 C8]Within[50]ms; | L6: Pass
A7: 2 | B7: 1.General 2.DiagnosticServices | C7: Diag_0x10_Phy_002 | D7: Service 0x10 Default To Programming | E7: High | F7: 陈亚-80025578 | G7: Based on analysis of requirements | H7: 1.Power On; | I7: 1.Send DiagBy[Physical]Data[10 01]; 2.Send DiagBy[Physical]Data[10 02]; | J7: 1.Check DiagData[50 01 00 32 00 C8]Within[50]ms; 2.Check DiagData[7F 10 22]Within[50]ms; | L7: Pass
A8: 3 | B8: 1.General 2.DiagnosticServices | C8: Diag_0x10_Phy_003 | D8: Service 0x10 Default To Extended | E8: High | F8: 陈亚-80025578 | G8: Based on analysis of requirements | H8: 1.Power On; | I8: 1.Send DiagBy[Physical]Data[10 01]; 2.Send DiagBy[Physical]Data[10 03]; | J8: 1.Check DiagData[50 01 00 32 00 C8]Within[50]ms; 2.Check DiagData[50 03 00 32 00 C8]Within[50]ms; | L8: Pass
A9: 4 | B9: 1.General 2.DiagnosticServices | C9: Diag_0x10_Phy_004 | D9: Service 0x10 Extended To Default | E9: High | F9: 陈亚-80025578 | G9: Based on analysis of requirements | H9: 1.Power On; | I9: 1.Send DiagBy[Physical]Data[10 01]; 2.Delay[1000]ms; 3.Send DiagBy[Physical]Data[10 03]; 4.Send DiagBy[Physical]Data[10 01]; | J9: 1.Check DiagData[50 01 00 32 00 C8]Within[50]ms; 3.Check DiagData[50 03 00 32 00 C8]Within[50]ms; 4.Check DiagData[50 01 00 32 00 C8]Within[50]ms; | L9: Pass
A10: 5 | B10: 1.General 2.DiagnosticServices | C10: Diag_0x10_Phy_005 | D10: Service 0x10 Extended To Programming | E10: High | F10: 陈亚-80025578 | G10: Based on analysis of requirements | H10: 1.Power On; | I10: 1.Send DiagBy[Physical]Data[10 01]; 2.Delay[1000]ms; 3.Send DiagBy[Physical]Data[10 03]; 4.Send DiagBy[Physical]Data[10 02]; | J10: 1.Check DiagData[50 01 00 32 00 C8]Within[50]ms; 3.Check DiagData[50 03 00 32 00 C8]Within[50]ms; 4.Check DiagData[50 02 00 32 00 C8]Within[50]ms; | L10: Pass
A11: 6 | B11: 1.General 2.DiagnosticServices | C11: Diag_0x10_Phy_006 | D11: Service 0x10 Extended To Extended | E11: High | F11: 陈亚-80025578 | G11: Based on analysis of requirements | H11: 1.Power On; | I11: 1.Send DiagBy[Physical]Data[10 01]; 2.Delay[1000]ms; 3.Send DiagBy[Physical]Data[10 03]; 4.Send DiagBy[Physical]Data[10 03]; | J11: 1.Check DiagData[50 01 00 32 00 C8]Within[50]ms; 3.Check DiagData[50 03 00 32 00 C8]Within[50]ms; 4.Check DiagData[50 03 00 32 00 C8]Within[50]ms; | L11: Pass
A12: 7 | B12: 1.General 2.DiagnosticServices | C12: Diag_0x10_Phy_007 | D12: Service 0x10 Programming To Default | E12: High | F12: 陈亚-80025578 | G12: Based on analysis of requirements | H12: 1.Power On; | I12: 1.Send DiagBy[Physical]Data[10 01]; 2.Delay[1000]ms; 3.Send DiagBy[Physical]Data[10 03]; 4.Send DiagBy[Physical]Data[10 02]; 5.Send DiagBy[Physical]Data[10 01]; | J12: 1.Check DiagData[50 01 00 32 00 C8]Within[50]ms; 3.Check DiagData[50 03 00 32 00 C8]Within[50]ms; 4.Check DiagData[50 02 00 32 00 C8]Within[50]ms; 5.Check DiagData[50 01 00 32 00 C8]Within[50]ms; | L12: Pass
A13: 8 | B13: 1.General 2.DiagnosticServices | C13: Diag_0x10_Phy_008 | D13: Service 0x10 Programming To Programming | E13: High | F13: 陈亚-80025578 | G13: Based on analysis of requirements | H13: 1.Power On; | I13: 1.Send DiagBy[Physical]Data[10 01]; 2.Delay[1000]ms; 3.Send DiagBy[Physical]Data[10 03]; 4.Send DiagBy[Physical]Data[10 02]; 5.Send DiagBy[Physical]Data[10 02]; | J13: 1.Check DiagData[50 01 00 32 00 C8]Within[50]ms; 3.Check DiagData[50 03 00 32 00 C8]Within[50]ms; 4.Check DiagData[50 02 00 32 00 C8]Within[50]ms; 5.Check DiagData[50 02 00 32 00 C8]Within[50]ms; | L13: Pass
A14: 9 | B14: 1.General 2.DiagnosticServices | C14: Diag_0x10_Phy_009 | D14: Service 0x10 Programming To Extended | E14: High | F14: 陈亚-80025578 | G14: Based on analysis of requirements | H14: 1.Power On; | I14: 1.Send DiagBy[Physical]Data[10 01]; 2.Delay[1000]ms; 3.Send DiagBy[Physical]Data[10 03]; 4.Send DiagBy[Physical]Data[10 02]; 5.Send DiagBy[Physical]Data[10 03]; | J14: 1.Check DiagData[50 01 00 32 00 C8]Within[50]ms; 3.Check DiagData[50 03 00 32 00 C8]Within[50]ms; 4.Check DiagData[50 02 00 32 00 C8]Within[50]ms; 5.Check DiagData[50 03 00 32 00 C8]Within[50]ms; | L14: Pass
A15: 1.2 SPRMIB Test
A16: 10 | B16: 1.General 2.DiagnosticServices | C16: Diag_0x10_Phy_010 | D16: Service 0x10 Default To Default with SPRMIB | E16: High | F16: 陈亚-80025578 | G16: Based on analysis of requirements | H16: 1.Power On; | I16: 1.Send DiagBy[Physical]Data[10 01]; 2.Send DiagBy[Physical]Data[10 81]; | J16: 1.Check DiagData[50 01 00 32 00 C8]Within[50]ms; 2.Check No_Response Within[1000]ms; | L16: Pass
A17: 11 | B17: 1.General 2.DiagnosticServices | C17: Diag_0x10_Phy_011 | D17: Service 0x10 Default To Programming with SPRMIB | E17: High | F17: 陈亚-80025578 | G17: Based on analysis of requirements | H17: 1.Power On; | I17: 1.Send DiagBy[Physical]Data[10 01]; 2.Send DiagBy[Physical]Data[10 82]; | J17: 1.Check DiagData[50 01 00 32 00 C8]Within[50]ms; 2.Check DiagData[7F 10 22]Within[50]ms; | K17: NRC回复错误，此时应该回复NRC 12,因为在表格中编程会话不支持抑制位 | L17: Fail
A18: 12 | B18: 1.General 2.DiagnosticServices | C18: Diag_0x10_Phy_012 | D18: Service 0x10 Default To Extended with SPRMIB | E18: High | F18: 陈亚-80025578 | G18: Based on analysis of requirements | H18: 1.Power On; | I18: 1.Send DiagBy[Physical]Data[10 01]; 2.Send DiagBy[Physical]Data[10 83]; | J18: 1.Check DiagData[50 01 00 32 00 C8]Within[50]ms; 2.Check No_Response Within[1000]ms; | L18: Pass
A19: 13 | B19: 1.General 2.DiagnosticServices | C19: Diag_0x10_Phy_013 | D19: Service 0x10 Extended To Default with SPRMIB | E19: High | F19: 陈亚-80025578 | G19: Based on analysis of requirements | H19: 1.Power On; | I19: 1.Send DiagBy[Physical]Data[10 01]; 2.Delay[1000]ms; 3.Send DiagBy[Physical]Data[10 03]; 4.Send DiagBy[Physical]Data[10 81]; | J19: 1.Check DiagData[50 01 00 32 00 C8]Within[50]ms; 3.Check DiagData[50 03 00 32 00 C8]Within[50]ms; 4.Check No_Response Within[1000]ms; | L19: Pass
A20: 14 | B20: 1.General 2.DiagnosticServices | C20: Diag_0x10_Phy_014 | D20: Service 0x10 Extended To Programming with SPRMIB | E20: High | F20: 陈亚-80025578 | G20: Based on analysis of requirements | H20: 1.Power On; | I20: 1.Send DiagBy[Physical]Data[10 01]; 2.Delay[1000]ms; 3.Send DiagBy[Physical]Data[10 03]; 4.Send DiagBy[Physical]Data[10 82]; | J20: 1.Check DiagData[50 01 00 32 00 C8]Within[50]ms; 3.Check DiagData[50 03 00 32 00 C8]Within[50]ms; 4.Check DiagData[50 02 00 32 00 C8]Within[50]ms; | K20: NRC回复错误，此时应该回复NRC 12,因为在表格中编程会话不支持抑制位 | L20: Fail
A21: 15 | B21: 1.General 2.DiagnosticServices | C21: Diag_0x10_Phy_015 | D21: Service 0x10 Extended To Extended with SPRMIB | E21: High | F21: 陈亚-80025578 | G21: Based on analysis of requirements | H21: 1.Power On; | I21: 1.Send DiagBy[Physical]Data[10 01]; 2.Delay[1000]ms; 3.Send DiagBy[Physical]Data[10 03]; 4.Send DiagBy[Physical]Data[10 83]; | J21: 1.Check DiagData[50 01 00 32 00 C8]Within[50]ms; 3.Check DiagData[50 03 00 32 00 C8]Within[50]ms; 4.Check No_Response Within[1000]ms; | L21: Pass
A22: 16 | B22: 1.General 2.DiagnosticServices | C22: Diag_0x10_Phy_016 | D22: Service 0x10 Programming To Default with SPRMIB | E22: High | F22: 陈亚-80025578 | G22: Based on analysis of requirements | H22: 1.Power On; | I22: 1.Send DiagBy[Physical]Data[10 01]; 2.Delay[1000]ms; 3.Send DiagBy[Physical]Data[10 03]; 4.Send DiagBy[Physical]Data[10 02]; 5.Send DiagBy[Physical]Data[10 81]; | J22: 1.Check DiagData[50 01 00 32 00 C8]Within[50]ms; 3.Check DiagData[50 03 00 32 00 C8]Within[50]ms; 4.Check DiagData[50 02 00 32 00 C8]Within[50]ms; 5.Check No_Response Within[1000]ms; | L22: Pass
A23: 17 | B23: 1.General 2.DiagnosticServices | C23: Diag_0x10_Phy_017 | D23: Service 0x10 Programming To Programming with SPRMIB | E23: High | F23: 陈亚-80025578 | G23: Based on analysis of requirements | H23: 1.Power On; | I23: 1.Send DiagBy[Physical]Data[10 01]; 2.Delay[1000]ms; 3.Send DiagBy[Physical]Data[10 03]; 4.Send DiagBy[Physical]Data[10 02]; 5.Send DiagBy[Physical]Data[10 82]; | J23: 1.Check DiagData[50 01 00 32 00 C8]Within[50]ms; 3.Check DiagData[50 03 00 32 00 C8]Within[50]ms; 4.Check DiagData[50 02 00 32 00 C8]Within[50]ms; 5.Check DiagData[50 02 00 32 00 C8]Within[50]ms; | K23: NRC回复错误，此时应该回复NRC 12,因为在表格中编程会话不支持抑制位 | L23: Fail
A24: 18 | B24: 1.General 2.DiagnosticServices | C24: Diag_0x10_Phy_018 | D24: Service 0x10 Programming To Extended with SPRMIB | E24: High | F24: 陈亚-80025578 | G24: Based on analysis of requirements | H24: 1.Power On; | I24: 1.Send DiagBy[Physical]Data[10 01]; 2.Delay[1000]ms; 3.Send DiagBy[Physical]Data[10 03]; 4.Send DiagBy[Physical]Data[10 02]; 5.Send DiagBy[Physical]Data[10 83]; | J24: 1.Check DiagData[50 01 00 32 00 C8]Within[50]ms; 3.Check DiagData[50 03 00 32 00 C8]Within[50]ms; 4.Check DiagData[50 02 00 32 00 C8]Within[50]ms; 5.Check No_Response Within[1000]ms; | L24: Pass
A25: 1.3 Secure Access Test
A26: 19 | B26: 1.General 2.DiagnosticServices | C26: Diag_0x10_Phy_019 | D26: Security access L1 unlock supports jumping to Programming Session | E26: High | F26: 陈亚-80025578 | G26: Based on analysis of requirements | H26: 1.Power On; | I26: 1.Send DiagBy[Physical]Data[10 01]; 2.Delay[1000]ms; 3.Send DiagBy[Physical]Data[10 03]; 4.Send DiagBy[Physical]Data[27 01]AndCheckResp[PositiveResponse]; 5.Send Security Right KeyBy[Physical]Level[02]; 6.Send DiagBy[Physical]Data[10 02]; | J26: 1.Check DiagData[50 01 00 32 00 C8]Within[50]ms; 3.Check DiagData[50 03 00 32 00 C8]Within[50]ms; 5.Check DiagData[67 02]Within[50]ms; 6.Check DiagData[50 02 00 32 00 C8]Within[50]ms; | L26: Pass
A27: 1.4 ECU Reset Test
A28: 20 | B28: 1.General 2.DiagnosticServices | C28: Diag_0x10_Phy_020 | D28: ECU Power reset Session returns to the Default Session | E28: Low | F28: 陈亚-80025578 | G28: Based on analysis of requirements | H28: 1.Power On; | I28: 1.Send DiagBy[Physical]Data[10 01]; 2.Delay[1000]ms; 3.Send DiagBy[Physical]Data[10 03]; 4.Set Voltage[0]V; 5.Delay[3000]ms; 6.Set Voltage[12]V; 7.Delay[3000]ms; 8.Send DiagBy[Physical]Data[27 01]; | J28: 1.Check DiagData[50 01 00 32 00 C8]Within[50]ms; 3.Check DiagData[50 03 00 32 00 C8]Within[50]ms; 8.Check DiagData[7F 27 7F]Within[50]ms; | L28: Pass
A29: 21 | B29: 1.General 2.DiagnosticServices | C29: Diag_0x10_Phy_021 | D29: ECU HardReset reset Session returns to the Default Session | E29: Low | F29: 陈亚-80025578 | G29: Based on analysis of requirements | H29: 1.Power On; | I29: 1.Send DiagBy[Physical]Data[10 01]; 2.Delay[1000]ms; 3.Send DiagBy[Physical]Data[10 03]; 4.Send DiagBy[Physical]Data[11 01]; 5.Delay[1000]ms; 6.Send DiagBy[Physical]Data[27 01]; | J29: 1.Check DiagData[50 01 00 32 00 C8]Within[50]ms; 3.Check DiagData[50 03 00 32 00 C8]Within[50]ms; 4.Check DiagData[51 01]Within[50]ms; 6.Check DiagData[7F 27 7F]Within[50]ms; | L29: Pass
A30: 1.5 Sub-function Traversal Test
A31: 22 | B31: 1.General 2.DiagnosticServices | C31: Diag_0x10_Phy_022 | D31: Subfunction traversal test in the Default Session | E31: Medium | F31: 陈亚-80025578 | G31: Based on analysis of requirements | H31: 1.Power On; | I31: 1.Send DiagBy[Physical]Data[10 01]; 2.Send SubTraversalBy[Physical]Service[0x10]Excluding[01 02 03 81 83]AndCheckResp[0x12]; | J31: 1.Check DiagData[50 01 00 32 00 C8]Within[50]ms; | L31: Pass
A32: 23 | B32: 1.General 2.DiagnosticServices | C32: Diag_0x10_Phy_023 | D32: Subfunction traversal test in the Extended Session | E32: Medium | F32: 陈亚-80025578 | G32: Based on analysis of requirements | H32: 1.Power On; | I32: 1.Send DiagBy[Physical]Data[10 01]; 2.Delay[1000]ms; 3.Send DiagBy[Physical]Data[10 03]; 4.Send SubTraversalBy[Physical]Service[0x10]Excluding[01 02 03 81 83]AndCheckResp[0x12]; | J32: 1.Check DiagData[50 01 00 32 00 C8]Within[50]ms; 3.Check DiagData[50 03 00 32 00 C8]Within[50]ms; | L32: Pass
A33: 24 | B33: 1.General 2.DiagnosticServices | C33: Diag_0x10_Phy_024 | D33: Subfunction traversal test in the Programming Session | E33: Medium | F33: 陈亚-80025578 | G33: Based on analysis of requirements | H33: 1.Power On; | I33: 1.Send DiagBy[Physical]Data[10 01]; 2.Delay[1000]ms; 3.Send DiagBy[Physical]Data[10 03]; 4.Send DiagBy[Physical]Data[10 02]; 5.Send SubTraversalBy[Physical]Service[0x10]Excluding[01 02 03 81 83]AndCheckResp[0x12]; | J33: 1.Check DiagData[50 01 00 32 00 C8]Within[50]ms; 3.Check DiagData[50 03 00 32 00 C8]Within[50]ms; 4.Check DiagData[50 02 00 32 00 C8]Within[50]ms; | L33: Pass
A34: 1.6 S3 Server Timer Test
A35: 25 | B35: 1.General 2.DiagnosticServices | C35: Diag_0x10_Phy_025 | D35: S3Server maintains the Session without timeout | E35: High | F35: 陈亚-80025578 | G35: Based on analysis of requirements | H35: 1.Power On; | I35: 1.Send DiagBy[Physical]Data[10 01]; 2.Delay[1000]ms; 3.Send DiagBy[Physical]Data[10 03]; 4.Delay[4900]ms; 5.Send DiagBy[Physical]Data[27 01]; | J35: 1.Check DiagData[50 01 00 32 00 C8]Within[50]ms; 3.Check DiagData[50 03 00 32 00 C8]Within[50]ms; 5.Check DiagData[67 01]Within[50]ms; | K35: 测似步骤5中，函数使用错误 | L35: Fail
A36: 26 | B36: 1.General 2.DiagnosticServices | C36: Diag_0x10_Phy_026 | D36: S3Server returns to the default Session upon timeout | E36: High | F36: 陈亚-80025578 | G36: Based on analysis of requirements | H36: 1.Power On; | I36: 1.Send DiagBy[Physical]Data[10 01]; 2.Delay[1000]ms; 3.Send DiagBy[Physical]Data[10 03]; 4.Delay[5100]ms; 5.Send DiagBy[Physical]Data[27 01]; | J36: 1.Check DiagData[50 01 00 32 00 C8]Within[50]ms; 3.Check DiagData[50 03 00 32 00 C8]Within[50]ms; 5.Check DiagData[7F 27 7F]Within[50]ms; | L36: Pass
A37: 1.7 Incorrect Diagnostic Command Test
A38: 27 | B38: 1.General 2.DiagnosticServices | C38: Diag_0x10_Phy_027 | D38: Valid SF_DL=2, invalid SF_DL > 2 | E38: Low | F38: 陈亚-80025578 | G38: Based on analysis of requirements | H38: 1.Power On; | I38: 1.Send DiagBy[Physical]Data[10 01]; 2.Send DiagBy[Physical]Data[10 01]WithLen[3]; | J38: 1.Check DiagData[50 01 00 32 00 C8]Within[50]ms; 2.Check DiagData[7F 10 13]Within[50]ms; | L38: Pass
A39: 28 | B39: 1.General 2.DiagnosticServices | C39: Diag_0x10_Phy_028 | D39: Valid SF_DL=2, invalid SF_DL < 2 | E39: Low | F39: 陈亚-80025578 | G39: Based on analysis of requirements | H39: 1.Power On; | I39: 1.Send DiagBy[Physical]Data[10 01]; 2.Send DiagBy[Physical]Data[10 01]WithLen[1]; | J39: 1.Check DiagData[50 01 00 32 00 C8]Within[50]ms; 2.Check DiagData[7F 10 13]Within[50]ms; | L39: Pass
A40: 1.8 NRC Priority Test
...

Sheet ECUReset_0x11
B1: Test Level | C1: SYS.5
A2: Sequence Number | B2: System Requirement ID | C2: Test Case | G2: Design Method | H2: Precondition | I2: Test Procedure | J2: Expected Output | K2: Actual Output | L2: Judgement Result | M2: Defect ID
C3: ID | D3: Name | E3: Priority | F3: Author
A4: 1. Application Service_Physical Addressing
A5: 1.1 Session Layer Test
A6: 1 | B6: 1.General 2.DiagnosticServices | C6: Diag_0x11_Phy_001 | D6: Default Session nonsupport 0x11 services | E6: High | F6: 陈亚-80025578 | G6: Based on analysis of requirements | H6: 1.Power On; | I6: 1.Send DiagBy[Physical]Data[10 01]; | J6: 1.Check DiagData[50 01 00 32 00 C8]Within[50]ms; | K6: 缺少主要步骤，当前应该是在默认会话下验证Service 0x11 | L6: Fail
A7: 2 | B7: 1.General 2.DiagnosticServices | C7: Diag_0x11_Phy_002 | D7: Programming Session support the 0x11 service 0x01 subfunction | E7: High | F7: 陈亚-80025578 | G7: Based on analysis of requirements | H7: 1.Power On; | I7: 1.Send DiagBy[Physical]Data[10 01]; 2.Delay[1000]ms; 3.Send DiagBy[Physical]Data[10 03]; 4.Delay[1000]ms; 5.Send DiagBy[Physical]Data[10 02]; 6.Send DiagBy[Physical]Data[11 01]; 7.Delay[1000]ms; | J7: 1.Check DiagData[50 01 00 32 00 C8]Within[50]ms; 3.Check DiagData[50 03 00 32 00 C8]Within[50]ms; 5.Check DiagData[50 02 00 32 00 C8]Within[50]ms; 6.Check DiagData[51 01]Within[50]ms; | L7: Pass
A8: 3 | B8: 1.General 2.DiagnosticServices | C8: Diag_0x11_Phy_003 | D8: Extended Session support the 0x11 service 0x01 subfunction | E8: High | F8: 陈亚-80025578 | G8: Based on analysis of requirements | H8: 1.Power On; | I8: 1.Send DiagBy[Physical]Data[10 01]; 2.Delay[1000]ms; 3.Send DiagBy[Physical]Data[10 03]; 4.Send DiagBy[Physical]Data[11 01]; 5.Delay[1000]ms; | J8: 1.Check DiagData[50 01 00 32 00 C8]Within[50]ms; 3.Check DiagData[50 03 00 32 00 C8]Within[50]ms; 4.Check DiagData[51 01]Within[50]ms; | L8: Pass
A9: 1.2 SPRMIB Test
A10: 4 | B10: 1.General 2.DiagnosticServices | C10: Diag_0x11_Phy_004 | D10: Programming Session support the 0x11 service 0x01 subfunction with SPRMIB | E10: High | F10: 陈亚-80025578 | G10: Based on analysis of requirements | H10: 1.Power On; | I10: 1.Send DiagBy[Physical]Data[10 01]; 2.Delay[1000]ms; 3.Send DiagBy[Physical]Data[10 03]; 4.Delay[1000]ms; 5.Send DiagBy[Physical]Data[10 02]; 6.Send DiagBy[Physical]Data[11 81]; | J10: 1.Check DiagData[50 01 00 32 00 C8]Within[50]ms; 3.Check DiagData[50 03 00 32 00 C8]Within[50]ms; 5.Check DiagData[50 02 00 32 00 C8]Within[50]ms; 6.Check DiagData[7F 11 12]Within[50]ms; | L10: Pass
A11: 5 | B11: 1.General 2.DiagnosticServices | C11: Diag_0x11_Phy_005 | D11: Extended Session support the 0x11 service 0x01 subfunction with SPRMIB | E11: High | F11: 陈亚-80025578 | G11: Based on analysis of requirements | H11: 1.Power On; | I11: 1.Send DiagBy[Physical]Data[10 01]; 2.Delay[1000]ms; 3.Send DiagBy[Physical]Data[10 03]; 4.Send DiagBy[Physical]Data[11 81]; | J11: 1.Check DiagData[50 01 00 32 00 C8]Within[50]ms; 3.Check DiagData[50 03 00 32 00 C8]Within[50]ms; 4.Check DiagData[7F 11 12]Within[50]ms; | L11: Pass
A12: 6 | B12: 1.General 2.DiagnosticServices | C12: Diag_0x11_Phy_006 | D12: Default Session nonsupport 0x11 services with SPRMIB | E12: High | F12: 陈亚-80025578 | G12: Based on analysis of requirements | H12: 1.Power On; | I12: 1.Send DiagBy[Physical]Data[10 01]; 2.Send DiagBy[Physical]Data[11 81]; | J12: 1.Check DiagData[50 01 00 32 00 C8]Within[50]ms; 2.Check DiagData[7F 11 7F]Within[50]ms; | L12: Pass
A13: 1.3 Secure Access Test
A14: 7 | B14: 1.General 2.DiagnosticServices | C14: Diag_0x11_Phy_007 | D14: Security access L1 unlock supports 0x11 service 0x01 subfunction | E14: High | F14: 陈亚-80025578 | G14: Based on analysis of requirements | H14: 1.Power On; | I14: 1.Send DiagBy[Physical]Data[10 01]; 2.Delay[1000]ms; 3.Send DiagBy[Physical]Data[10 03]; 4.Send DiagBy[Physical]Data[27 01]AndCheckResp[PositiveResponse]; 5.Send Security Right KeyBy[Physical]Level[02]; 6.Send DiagBy[Physical]Data[11 01]; 7.Delay[1000]ms; | J14: 1.Check DiagData[50 01 00 32 00 C8]Within[50]ms; 3.Check DiagData[50 03 00 32 00 C8]Within[50]ms; 5.Check DiagData[67 02]Within[50]ms; 6.Check DiagData[51 01]Within[50]ms; | L14: Pass
A15: A. Service Reset
A16: 8 | B16: 1.General 2.DiagnosticServices | C16: Diag_0x11_Phy_008 | D16: 0x11 Service 0x01 subfunction non-Default Session to Default Session | E16: High | F16: 陈亚-80025578 | G16: Based on analysis of requirements | H16: 1.Power On; | I16: 1.Send DiagBy[Physical]Data[10 01]; 2.Delay[1000]ms; 3.Send DiagBy[Physical]Data[10 03]; 4.Send DiagBy[Physical]Data[11 01]; 5.Delay[1000]ms; 6.Send DiagBy[Physical]Data[22 F6 C3]; | J16: 1.Check DiagData[50 01 00 32 00 C8]Within[50]ms; 3.Check DiagData[50 03 00 32 00 C8]Within[50]ms; 4.Check DiagData[51 01]Within[50]ms; 6.Check DiagData[62 F6 C3]Within[50]ms; | K16: 需要填充数据，但目前调查表没有给出对应格式 | L16: Fail
A17: B. Security Access Reset
A18: 9 | B18: 1.General 2.DiagnosticServices | C18: Diag_0x11_Phy_009 | D18: 0x11 Service 0x01 subfunction Security access reset | E18: High | F18: 陈亚-80025578 | G18: Based on analysis of requirements | H18: 1.Power On; | I18: 1.Send DiagBy[Physical]Data[10 01]; 2.Delay[1000]ms; 3.Send DiagBy[Physical]Data[10 03]; 4.Send DiagBy[Physical]Data[27 01]AndCheckResp[PositiveResponse]; 5.Send Security Right KeyBy[Physical]Level[02]; 6.Send DiagBy[Physical]Data[11 01]; 7.Delay[1000]ms; 8.Send DiagBy[Physical]Data[22 F6 C3]; 9.Send DiagBy[Physical]Data[10 03]; 10.Send DiagBy[Physical]Data[27 01]; | J18: 1.Check DiagData[50 01 00 32 00 C8]Within[50]ms; 3.Check DiagData[50 03 00 32 00 C8]Within[50]ms; 5.Check DiagData[67 02]Within[50]ms; 6.Check DiagData[51 01]Within[50]ms; 8.Check DiagData[62 F6 C3]Within[50]ms; 9.Check DiagData[50 03 00 32 00 C8]Within[50]ms; 10.Check DiagData[67 01]Within[50]ms; | K18: 测试过程第10步，函数使用错误，应该使用Send DiagBy[Physical]Data[27 01]AndCheckResp[PositiveResponse]; | L18: Fail
A19: C. Communication Control State Reset
A20: 10 | B20: 1.General 2.DiagnosticServices | C20: Diag_0x11_Phy_010 | D20: 0x11 Service 0x01 subfunction communication control state reset | E20: High | F20: 陈亚-80025578 | G20: Based on analysis of requirements | H20: 1.Power On; | I20: 1.Send DiagBy[Physical]Data[10 01]; 2.Delay[1000]ms; 3.Send DiagBy[Physical]Data[10 03]; 4.Send DiagBy[Physical]Data[28 01 01]; 5.Send DiagBy[Physical]Data[11 01]; 6.Delay[1000]ms; 7.Send DiagBy[Physical]Data[22 F6 C3]; | J20: 1.Check DiagData[50 01 00 32 00 C8]Within[50]ms; 3.Check DiagData[50 03 00 32 00 C8]Within[50]ms; 4.Check DiagData[68 01]Within[50]ms; 5.Check DiagData[51 01]Within[50]ms; 7.Check DiagData[62 F6 C3]Within[50]ms; | K20: 仅验证服务本身就行，这里发送了Service 0x28，与后面重复，且这里未做任何与信号相关的检查 | L20: Fail
A21: 1.5 Sub-function Traversal Test
A22: 11 | B22: 1.General 2.DiagnosticServices | C22: Diag_0x11_Phy_011 | D22: Subfunction traversal test in the Default Session | E22: Medium | F22: 陈亚-80025578 | G22: Based on analysis of requirements | H22: 1.Power On; | I22: 1.Send DiagBy[Physical]Data[10 01]; 2.Send SubTraversalBy[Physical]Service[0x11]Excluding[01 81]AndCheckResp[0x7F]; | J22: 1.Check DiagData[50 01 00 32 00 C8]Within[50]ms; | L22: Pass
A23: 12 | B23: 1.General 2.DiagnosticServices | C23: Diag_0x11_Phy_012 | D23: Subfunction traversal test in the Programming Session | E23: Medium | F23: 陈亚-80025578 | G23: Based on analysis of requirements | H23: 1.Power On; | I23: 1.Send DiagBy[Physical]Data[10 01]; 2.Delay[1000]ms; 3.Send DiagBy[Physical]Data[10 03]; 4.Delay[1000]ms; 5.Send DiagBy[Physical]Data[10 02]; 6.Send SubTraversalBy[Physical]Service[0x11]Excluding[01 81]AndCheckResp[0x12]; | J23: 1.Check DiagData[50 01 00 32 00 C8]Within[50]ms; 3.Check DiagData[50 03 00 32 00 C8]Within[50]ms; 5.Check DiagData[50 02 00 32 00 C8]Within[50]ms; | L23: Pass
A24: 13 | B24: 1.General 2.DiagnosticServices | C24: Diag_0x11_Phy_013 | D24: Subfunction traversal test in the Extended Session | E24: Medium | F24: 陈亚-80025578 | G24: Based on analysis of requirements | H24: 1.Power On; | I24: 1.Send DiagBy[Physical]Data[10 01]; 2.Delay[1000]ms; 3.Send DiagBy[Physical]Data[10 03]; 4.Send SubTraversalBy[Physical]Service[0x11]Excluding[01 81]AndCheckResp[0x12]; | J24: 1.Check DiagData[50 01 00 32 00 C8]Within[50]ms; 3.Check DiagData[50 03 00 32 00 C8]Within[50]ms; | L24: Pass
A25: A. DLC Error Test
A26: 14 | B26: 1.General 2.DiagnosticServices | C26: Diag_0x11_Phy_014 | D26: When a diagnostic message with DLC < 8 is sent, ECU does not respond | E26: Low | F26: 陈亚-80025578 | G26: Based on analysis of requirements | H26: 1.Power On; | I26: 1.Send DiagBy[Physical]Data[10 01]; 2.Delay[1000]ms; 3.Send DiagBy[Physical]Data[10 03]; 4.Send Msg[ReqCANID]Data[02 11 01]WithDLC[7]; | J26: 1.Check DiagData[50 01 00 32 00 C8]Within[50]ms; 3.Check DiagData[50 03 00 32 00 C8]Within[50]ms; 4.Check No_Response Within[1000]ms; | L26: Pass
A27: 15 | B27: 1.General 2.DiagnosticServices | C27: Diag_0x11_Phy_015 | D27: When a diagnostic message with DLC > 8 is sent, ECU responds normally | E27: Low | F27: 陈亚-80025578 | G27: Based on analysis of requirements | H27: 1.Power On; | I27: 1.Send DiagBy[Physical]Data[10 01]; 2.Delay[1000]ms; 3.Send DiagBy[Physical]Data[10 03]; 4.Send Msg[ReqCANID]Data[02 11 01]WithDLC[9]; | J27: 1.Check DiagData[50 01 00 32 00 C8]Within[50]ms; 3.Check DiagData[50 03 00 32 00 C8]Within[50]ms; 4.Check DiagData[51 01]Within[50]ms; | L27: Pass
A28: B. NRC Priority Test
A29: 16 | B29: 1.General 2.DiagnosticServices | C29: Diag_0x11_Phy_016 | D29: NRC 13(min Size) > 12 | E29: High | F29: 陈亚-80025578 | G29: Based on analysis of requirements | H29: 1.Power On; | I29: 1.Send DiagBy[Physical]Data[10 01]; 2.Delay[1000]ms; 3.Send DiagBy[Physical]Data[10 03]; 4.Send Msg[ReqCANID]Data[01 11]WithDLC[8]; | J29: 1.Check DiagData[50 01 00 32 00 C8]Within[50]ms; 3.Check DiagData[50 03 00 32 00 C8]Within[50]ms; 4.Check DiagData[7F 11 13]Within[50]ms; | L29: Pass
A30: 17 | B30: 1.General 2.DiagnosticServices | C30: Diag_0x11_Phy_017 | D30: NRC 12 > 7E | E30: High | F30: 陈亚-80025578 | G30: Based on analysis of requirements | H30: 1.Power On; | I30: 1.Send DiagBy[Physical]Data[10 01]; 2.Send DiagBy[Physical]Data[11 02]; | J30: 1.Check DiagData[50 01 00 32 00 C8]Within[50]ms; 2.Check DiagData[7F 11 12]Within[50]ms; | L30: Pass
A31: 18 | B31: 1.General 2.DiagnosticServices | C31: Diag_0x11_Phy_018 | D31: NRC 7E > 22 | E31: High | F31: 陈亚-80025578 | G31: Based on analysis of requirements | H31: 1.Power On; | I31: 1.Send DiagBy[Physical]Data[10 01]; 2.Send DiagBy[Physical]Data[11 01]; | J31: 1.Check DiagData[50 01 00 32 00 C8]Within[50]ms; 2.Check DiagData[7F 11 7F]Within[50]ms; | L31: Pass
A32: C. Voltage Condition Test
A33: 19 | B33: 1.General 2.DiagnosticServices | C33: Diag_0x11_Phy_019 | D33: When the preset voltage condition is not met (low), NRC 0x22 is reported | E33: High | F33: 陈亚-80025578 | G33: Based on analysis of requirements | H33: 1.Power On; | I33: 1.Send DiagBy[Physical]Data[10 01]; 2.Delay[1000]ms; 3.Send DiagBy[Physical]Data[10 03]; 4.Set Voltage[6.8]V; 5.Delay[3000]ms; 6.Send DiagBy[Physical]Data[11 01]; | J33: 1.Check DiagData[50 01 00 32 00 C8]Within[50]ms; 3.Check DiagData[50 03 00 32 00 C8]Within[50]ms; 6.Check DiagData[7F 11 22]Within[50]ms; | L33: Pass
A34: 20 | B34: 1.General 2.DiagnosticServices | C34: Diag_0x11_Phy_020 | D34: When the preset voltage condition is not met (high), NRC 0x22 is reported | E34: High | F34: 陈亚-80025578 | G34: Based on analysis of requirements | H34: 1.Power On; | I34: 1.Send DiagBy[Physical]Data[10 01]; 2.Delay[1000]ms; 3.Send DiagBy[Physical]Data[10 03]; 4.Set Voltage[18.0]V; 5.Delay[3000]ms; 6.Send DiagBy[Physical]Data[11 01]; | J34: 1.Check DiagData[50 01 00 32 00 C8]Within[50]ms; 3.Check DiagData[50 03 00 32 00 C8]Within[50]ms; 6.Check DiagData[7F 11 22]Within[50]ms; | L34: Pass
A35: 1.7 Functional Addressing Test
A36: 21 | B36: 1.General 2.DiagnosticServices | C36: Diag_0x11_Phy_021 | D36: 0x11 Service nonsupport functional addressing subfunction 0x01 | E36: High | F36: 陈亚-80025578 | G36: Based on analysis of requirements | H36: 1.Power On; | I36: 1.Send DiagBy[Physical]Data[10 01]; 2.Delay[1000]ms; 3.Send DiagBy[Physical]Data[10 03]; 4.Send DiagBy[Function]Data[11 01]; 5.Delay[1000]ms; | J36: 1.Check DiagData[50 01 00 32 00 C8]Within[50]ms; 3.Check DiagData[50 03 00 32 00 C8]Within[50]ms; 4.Check No_Response Within[1000]ms; | L36: Pass
A37: 22 | B37: 1.General 2.DiagnosticServices | C37: Diag_0x11_Phy_022 | D37: 0x11 Service nonsupport functional addressing subfunction 0x02 | E37: High | F37: 陈亚-80025578 | G37: Based on analysis of requirements | H37: 1.Power On; | I37: 1.Send DiagBy[Physical]Data[10 01]; 2.Delay[1000]ms; 3.Send DiagBy[Physical]Data[10 03]; 4.Send DiagBy[Function]Data[11 02]; 5.Delay[1000]ms; | J37: 1.Check DiagData[50 01 00 32 00 C8]Within[50]ms; 3.Check DiagData[50 03 00 32 00 C8]Within[50]ms; 4.Check No_Response Within[1000]ms; | L37: Pass
A38: 23 | B38: 1.General 2.DiagnosticServices | C38: Diag_0x11_Phy_023 | D38: 0x11 Service nonsupport functional addressing subfunction 0x03 | E38: High | F38: 陈亚-80025578 | G38: Based on analysis of requirements | H38: 1.Power On; | I38: 1.Send DiagBy[Physical]Data[10 01]; 2.Delay[1000]ms; 3.Send DiagBy[Physical]Data[10 03]; 4.Send DiagBy[Function]Data[11 03]; 5.Delay[1000]ms; | J38: 1.Check DiagData[50 01 00 32 00 C8]Within[50]ms; 3.Check DiagData[50 03 00 32 00 C8]Within[50]ms; 4.Check No_Response Within[1000]ms; | L38: Pass
A39: 3. Boot Service_Physical Addressing
A40: 3.1 Session Layer Test
...

Sheet ClearDiagnosticInformation_0x14
B1: Test Level | C1: SYS.5
A2: Sequence Number | B2: System Requirement ID | C2: Test Case | G2: Design Method | H2: Precondition | I2: Test Procedure | J2: Expected Output | K2: Actual Output | L2: Judgement Result | M2: Defect ID
C3: ID | D3: Name | E3: Priority | F3: Author
A4: 1. Application Service_Physical Addressing
A5: 1.1 Session Layer Test
A6: 1 | B6: 1.General 2.DiagnosticServices | C6: Diag_0x14_Phy_001 | D6: Default Session nonsupport 0x14 services | E6: High | F6: 陈亚-80025578 | G6: Based on analysis of requirements | H6: 1.Power On; | I6: 1. Send DiagBy[Physical]Data[10 01]; 2. Send DiagBy[Physical]Data[14 FF FF FF]; | J6: 1. Check DiagData[50 01 XX XX XX XX]Within[50]ms; 2. Check DiagData[7F 14 11]Within[50]ms; | K6: 未正确填充数据 | L6: Fail
A7: 2 | B7: 1.General 2.DiagnosticServices | C7: Diag_0x14_Phy_002 | D7: Extended Session nonsupport 0x14 services | E7: High | F7: 陈亚-80025578 | G7: Based on analysis of requirements | H7: 1.Power On; | I7: 1. Send DiagBy[Physical]Data[10 01]; 2. Send DiagBy[Physical]Data[10 03]; 3. Send DiagBy[Physical]Data[14 FF FF FF]; | J7: 1. Check DiagData[50 01 XX XX XX XX]Within[50]ms; 2. Check DiagData[50 03 XX XX XX XX]Within[50]ms; 3. Check DiagData[7F 14 11]Within[50]ms; | L7: Pass
A8: 3 | B8: 1.General 2.DiagnosticServices | C8: Diag_0x14_Phy_003 | D8: Programming Session nonsupport 0x14 services | E8: High | F8: 陈亚-80025578 | G8: Based on analysis of requirements | H8: 1.Power On; | I8: 1. Send DiagBy[Physical]Data[10 01]; 2. Delay[1000]ms; 3. Send DiagBy[Physical]Data[10 03]; 4. Send DiagBy[Physical]Data[31 01 02 03]; 5. Send DiagBy[Physical]Data[10 02]; 6. Send DiagBy[Physical]Data[14 FF FF FF]; | J8: 1. Check DiagData[50 01 XX XX XX XX]Within[50]ms; 3. Check DiagData[50 03 XX XX XX XX]Within[50]ms; 4. Check DiagData[71 01 02 03 00]Within[50]ms; 5. Check DiagData[50 02 XX XX XX XX]Within[50]ms; 6. Check DiagData[7F 14 11]Within[50]ms; | L8: Pass
A9: 2. Application Service_Functional Addressing
A10: 2.1 Session Layer Test
A11: 4 | B11: 1.General 2.DiagnosticServices | C11: Diag_0x14_Fun_001 | D11: Default Session nonsupport 0x14 services | E11: High | F11: 陈亚-80025578 | G11: Based on analysis of requirements | H11: 1.Power On; | I11: 1. Send DiagBy[Physical]Data[10 01]; 2. Send DiagBy[Function]Data[14 FF FF FF]; | J11: 1. Check DiagData[50 01 XX XX XX XX]Within[50]ms; 2. Check No_Response Within[1000]ms; | K11: 需要回复NRC 0x11 | L11: Fail
A12: 5 | B12: 1.General 2.DiagnosticServices | C12: Diag_0x14_Fun_002 | D12: Extended Session nonsupport 0x14 services | E12: High | F12: 陈亚-80025578 | G12: Based on analysis of requirements | H12: 1.Power On; | I12: 1. Send DiagBy[Physical]Data[10 01]; 2. Send DiagBy[Physical]Data[10 03]; 3. Send DiagBy[Function]Data[14 FF FF FF]; | J12: 1. Check DiagData[50 01 XX XX XX XX]Within[50]ms; 2. Check DiagData[50 03 XX XX XX XX]Within[50]ms; 3. Check No_Response Within[1000]ms; | K12: 需要回复NRC 0x11 | L12: Fail
A13: 6 | B13: 1.General 2.DiagnosticServices | C13: Diag_0x14_Fun_003 | D13: Programming Session nonsupport 0x14 services | E13: High | F13: 陈亚-80025578 | G13: Based on analysis of requirements | H13: 1.Power On; | I13: 1. Send DiagBy[Physical]Data[10 01]; 2. Delay[1000]ms; 3. Send DiagBy[Physical]Data[10 03]; 4. Send DiagBy[Physical]Data[31 01 02 03]; 5. Send DiagBy[Physical]Data[10 02]; 6. Send DiagBy[Function]Data[14 FF FF FF]; | J13: 1. Check DiagData[50 01 XX XX XX XX]Within[50]ms; 3. Check DiagData[50 03 XX XX XX XX]Within[50]ms; 4. Check DiagData[71 01 02 03 00]Within[50]ms; 5. Check DiagData[50 02 XX XX XX XX]Within[50]ms; 6. Check No_Response Within[1000]ms; | K13: 需要回复NRC 0x11 | L13: Fail
A14: 3. Boot Service_Physical Addressing
A15: 3.1 Session Layer Test
A16: 7 | B16: 1.General 2.DiagnosticServices | C16: Diag_0x14_Phy_004 | D16: Default Session nonsupport 0x14 services | E16: High | F16: 陈亚-80025578 | G16: Based on analysis of requirements | H16: 1.Power On; | I16: 1. Send DiagBy[Physical]Data[10 01]; 2. Delay[1000]ms; 3. Send DiagBy[Physical]Data[10 03]; 4. Send DiagBy[Physical]Data[31 01 02 03]; 5. Send DiagBy[Physical]Data[10 02]; 6. Send DiagBy[Physical]Data[10 01]; 7. Send DiagBy[Physical]Data[14 FF FF FF]; | J16: 1. Check DiagData[50 01 XX XX XX XX]Within[50]ms; 3. Check DiagData[50 03 XX XX XX XX]Within[50]ms; 4. Check DiagData[71 01 02 03 00]Within[50]ms; 5. Check DiagData[50 02 XX XX XX XX]Within[50]ms; 6. Check DiagData[50 01 XX XX XX XX]Within[50]ms; 7. Check DiagData[7F 14 11]Within[50]ms; | L16: Pass
A17: 8 | B17: 1.General 2.DiagnosticServices | C17: Diag_0x14_Phy_005 | D17: Programming Session nonsupport 0x14 services | E17: High | F17: 陈亚-80025578 | G17: Based on analysis of requirements | H17: 1.Power On; | I17: 1. Send DiagBy[Physical]Data[10 01]; 2. Delay[1000]ms; 3. Send DiagBy[Physical]Data[10 03]; 4. Send DiagBy[Physical]Data[31 01 02 03]; 5. Send DiagBy[Physical]Data[10 02]; 6. Send DiagBy[Physical]Data[14 FF FF FF]; | J17: 1. Check DiagData[50 01 XX XX XX XX]Within[50]ms; 3. Check DiagData[50 03 XX XX XX XX]Within[50]ms; 4. Check DiagData[71 01 02 03 00]Within[50]ms; 5. Check DiagData[50 02 XX XX XX XX]Within[50]ms; 6. Check DiagData[7F 14 11]Within[50]ms; | L17: Pass
A18: 9 | B18: 1.General 2.DiagnosticServices | C18: Diag_0x14_Phy_006 | D18: Extended Session nonsupport 0x14 services | E18: High | F18: 陈亚-80025578 | G18: Based on analysis of requirements | H18: 1.Power On; | I18: 1. Send DiagBy[Physical]Data[10 01]; 2. Delay[1000]ms; 3. Send DiagBy[Physical]Data[10 03]; 4. Send DiagBy[Physical]Data[31 01 02 03]; 5. Send DiagBy[Physical]Data[10 02]; 6. Send DiagBy[Physical]Data[10 03]; 7. Send DiagBy[Physical]Data[14 FF FF FF]; | J18: 1. Check DiagData[50 01 XX XX XX XX]Within[50]ms; 3. Check DiagData[50 03 XX XX XX XX]Within[50]ms; 4. Check DiagData[71 01 02 03 00]Within[50]ms; 5. Check DiagData[50 02 XX XX XX XX]Within[50]ms; 6. Check DiagData[50 03 XX XX XX XX]Within[50]ms; 7. Check DiagData[7F 14 11]Within[50]ms; | L18: Pass
A19: 4. Boot Service_Functional Addressing
A20: 4.1 Session Layer Test
A21: 10 | B21: 1.General 2.DiagnosticServices | C21: Diag_0x14_Fun_004 | D21: Default Session nonsupport 0x14 services | E21: High | F21: 陈亚-80025578 | G21: Based on analysis of requirements | H21: 1.Power On; | I21: 1. Send DiagBy[Physical]Data[10 01]; 2. Delay[1000]ms; 3. Send DiagBy[Physical]Data[10 03]; 4. Send DiagBy[Physical]Data[31 01 02 03]; 5. Send DiagBy[Physical]Data[10 02]; 6. Send DiagBy[Physical]Data[10 01]; 7. Send DiagBy[Function]Data[14 FF FF FF]; | J21: 1. Check DiagData[50 01 XX XX XX XX]Within[50]ms; 3. Check DiagData[50 03 XX XX XX XX]Within[50]ms; 4. Check DiagData[71 01 02 03 00]Within[50]ms; 5. Check DiagData[50 02 XX XX XX XX]Within[50]ms; 6. Check DiagData[50 01 XX XX XX XX]Within[50]ms; 7. Check No_Response Within[1000]ms; | K21: 1.31 01 02 03不支持 2.要回复NRC 0x11 | L21: Fail
A22: 11 | B22: 1.General 2.DiagnosticServices | C22: Diag_0x14_Fun_005 | D22: Programming Session nonsupport 0x14 services | E22: High | F22: 陈亚-80025578 | G22: Based on analysis of requirements | H22: 1.Power On; | I22: 1. Send DiagBy[Physical]Data[10 01]; 2. Delay[1000]ms; 3. Send DiagBy[Physical]Data[10 03]; 4. Send DiagBy[Physical]Data[31 01 02 03]; 5. Send DiagBy[Physical]Data[10 02]; 6. Send DiagBy[Function]Data[14 FF FF FF]; | J22: 1. Check DiagData[50 01 XX XX XX XX]Within[50]ms; 3. Check DiagData[50 03 XX XX XX XX]Within[50]ms; 4. Check DiagData[71 01 02 03 00]Within[50]ms; 5. Check DiagData[50 02 XX XX XX XX]Within[50]ms; 6. Check No_Response Within[1000]ms; | K22: 1.31 01 02 03不支持 2.要回复NRC 0x11 | L22: Fail
A23: 12 | B23: 1.General 2.DiagnosticServices | C23: Diag_0x14_Fun_006 | D23: Extended Session nonsupport 0x14 services | E23: High | F23: 陈亚-80025578 | G23: Based on analysis of requirements | H23: 1.Power On; | I23: 1. Send DiagBy[Physical]Data[10 01]; 2. Delay[1000]ms; 3. Send DiagBy[Physical]Data[10 03]; 4. Send DiagBy[Physical]Data[31 01 02 03]; 5. Send DiagBy[Physical]Data[10 02]; 6. Send DiagBy[Physical]Data[10 03]; 7. Send DiagBy[Function]Data[14 FF FF FF]; | J23: 1. Check DiagData[50 01 XX XX XX XX]Within[50]ms; 3. Check DiagData[50 03 XX XX XX XX]Within[50]ms; 4. Check DiagData[71 01 02 03 00]Within[50]ms; 5. Check DiagData[50 02 XX XX XX XX]Within[50]ms; 6. Check DiagData[50 03 XX XX XX XX]Within[50]ms; 7. Check No_Response Within[1000]ms; | K23: 1.31 01 02 03不支持 2.要回复NRC 0x11 | L23: Fail

Sheet SecurityAccess_0x27
B1: Test Level | C1: SYS.5
A2: Sequence Number | B2: System Requirement ID | C2: Test Case | G2: Design Method | H2: Precondition | I2: Test Procedure | J2: Expected Output | K2: Actual Output | L2: Judgement Result | M2: Defect ID
C3: ID | D3: Name | E3: Priority | F3: Author
A4: APP 域 Physical 寻址测试用例
A5: 1.1 Session Layer Test (APP)
A6: 1 | B6: 1.General 2.DiagnosticServices | C6: Diag_0x27_Phy_001 | D6: Default Session nonsupport 0x27 Service security access level 1 Negativecase-$27 | E6: High | F6: 陈亚-80025578 | G6: Based on analysis of requirements | H6: 1.Power On; | I6: 1.Send DiagBy[Physical]Data[10 01]; 2.Send DiagBy[Physical]Data[27 01]AndCheckResp[7F 27 7F]; | J6: 1.Check DiagData[50 01 XX XX XX XX]Within[50]ms; | K6: 格式错误 | L6: Fail
A7: 2 | B7: 1.General 2.DiagnosticServices | C7: Diag_0x27_Phy_002 | D7: Default Session nonsupport 0x27 Service security access level 2 Negativecase-$27 | E7: High | F7: 陈亚-80025578 | G7: Based on analysis of requirements | H7: 1.Power On; | I7: 1.Send DiagBy[Physical]Data[10 01]; 2.Send DiagBy[Physical]Data[27 03]AndCheckResp[7F 27 7F]; | J7: 1.Check DiagData[50 01 XX XX XX XX]Within[50]ms; | L7: Fail
A8: 3 | B8: 1.General 2.DiagnosticServices | C8: Diag_0x27_Phy_003 | D8: Programming Session support 0x27 Service security access level 1 PositiveResponsecase-$27 | E8: High | F8: 陈亚-80025578 | G8: Based on analysis of requirements | H8: 1.Power On; | I8: 1.Send DiagBy[Physical]Data[10 01]; 2.Delay[1000]ms; 3.Send DiagBy[Physical]Data[10 03]; 4.Send DiagBy[Physical]Data[31 01 02 03]; 5.Send DiagBy[Physical]Data[10 02]; 6.Send DiagBy[Physical]Data[27 01]AndCheckResp[PositiveResponse]; 7.Send Security Right KeyBy[Physical]Level[02]; | J8: 1.Check DiagData[50 01 XX XX XX XX]Within[50]ms; 3.Check DiagData[50 03 XX XX XX XX]Within[50]ms; 4.Check DiagData[71 01 02 03 00]Within[50]ms; 5.Check DiagData[50 02 XX XX XX XX]Within[50]ms; 7.Check DiagData[67 02]Within[50]ms; | K8: 不支持31 01 02 03 | L8: Fail
A9: 4 | B9: 1.General 2.DiagnosticServices | C9: Diag_0x27_Phy_004 | D9: Programming Session support 0x27 Service security access level 2 PositiveResponsecase-$27 | E9: High | F9: 陈亚-80025578 | G9: Based on analysis of requirements | H9: 1.Power On; | I9: 1.Send DiagBy[Physical]Data[10 01]; 2.Delay[1000]ms; 3.Send DiagBy[Physical]Data[10 03]; 4.Send DiagBy[Physical]Data[31 01 02 03]; 5.Send DiagBy[Physical]Data[10 02]; 6.Send DiagBy[Physical]Data[27 03]AndCheckResp[PositiveResponse]; 7.Send Security Right KeyBy[Physical]Level[04]; | J9: 1.Check DiagData[50 01 XX XX XX XX]Within[50]ms; 3.Check DiagData[50 03 XX XX XX XX]Within[50]ms; 4.Check DiagData[71 01 02 03 00]Within[50]ms; 5.Check DiagData[50 02 XX XX XX XX]Within[50]ms; 7.Check DiagData[67 04]Within[50]ms; | K9: 不支持31 01 02 03 | L9: Fail
A10: 5 | B10: 1.General 2.DiagnosticServices | C10: Diag_0x27_Phy_005 | D10: Extended Session support 0x27 Service security access level 1 PositiveResponsecase-$27 | E10: High | F10: 陈亚-80025578 | G10: Based on analysis of requirements | H10: 1.Power On; | I10: 1.Send DiagBy[Physical]Data[10 03]; 2.Send DiagBy[Physical]Data[27 01]AndCheckResp[PositiveResponse]; 3.Send Security Right KeyBy[Physical]Level[02]; | J10: 1.Check DiagData[50 03 XX XX XX XX]Within[50]ms; 3.Check DiagData[67 02]Within[50]ms; | L10: Pass
A11: 6 | B11: 1.General 2.DiagnosticServices | C11: Diag_0x27_Phy_006 | D11: Extended Session support 0x27 Service security access level 2 PositiveResponsecase-$27 | E11: High | F11: 陈亚-80025578 | G11: Based on analysis of requirements | H11: 1.Power On; | I11: 1.Send DiagBy[Physical]Data[10 03]; 2.Send DiagBy[Physical]Data[27 03]AndCheckResp[PositiveResponse]; 3.Send Security Right KeyBy[Physical]Level[04]; | J11: 1.Check DiagData[50 03 XX XX XX XX]Within[50]ms; 3.Check DiagData[67 04]Within[50]ms; | K11: 不支持27 03，这里要回复NRC 12，而不是PositiveResponse | L11: Fail
A12: 1.2 Secure Access Process Test (APP)
A13: 7 | B13: 1.General 2.DiagnosticServices | C13: Diag_0x27_Phy_007 | D13: Does not meet the secure access process, only requests seeds, a negative test case where secure access cannot be unlocked | E13: High | F13: 陈亚-80025578 | G13: Based on analysis of requirements | H13: 1.Power On; | I13: 1.Send DiagBy[Physical]Data[10 03]; 2.Send DiagBy[Physical]Data[27 01]AndCheckResp[PositiveResponse]; | J13: 1.Check DiagData[50 03 XX XX XX XX]Within[50]ms; | L13: Pass
A14: 8 | B14: 1.General 2.DiagnosticServices | C14: Diag_0x27_Phy_008 | D14: Does not meet the secure access process, only sending the key; a negative test case | E14: High | F14: 陈亚-80025578 | G14: Based on analysis of requirements | H14: 1.Power On; | I14: 1.Send DiagBy[Physical]Data[10 03]; 2.Send DiagBy[Physical]Data[27 02]; | J14: 1.Check DiagData[50 03 XX XX XX XX]Within[50]ms; 2.Check DiagData[7F 27 24]Within[50]ms; | L14: Pass
A15: 9 | B15: 1.General 2.DiagnosticServices | C15: Diag_0x27_Phy_009 | D15: Meet the secure access process: request the seed first, then send the key – a PositiveResponse use case | E15: High | F15: 陈亚-80025578 | G15: Based on analysis of requirements | H15: 1.Power On; | I15: 1.Send DiagBy[Physical]Data[10 03]; 2.Send DiagBy[Physical]Data[27 01]AndCheckResp[PositiveResponse]; 3.Send Security Right KeyBy[Physical]Level[02]; | J15: 1.Check DiagData[50 03 XX XX XX XX]Within[50]ms; 3.Check DiagData[67 02]Within[50]ms; | L15: Pass
A16: 10 | B16: 1.General 2.DiagnosticServices | C16: Diag_0x27_Phy_010 | D16: Failure to comply with the secure access process: sending the key first, then requesting the seed - same level | E16: High | F16: 陈亚-80025578 | G16: Based on analysis of requirements | H16: 1.Power On; | I16: 1.Send DiagBy[Physical]Data[10 03]; 2.Send DiagBy[Physical]Data[27 02]; 3.Send DiagBy[Physical]Data[27 01]AndCheckResp[PositiveResponse]; | J16: 1.Check DiagData[50 03 XX XX XX XX]Within[50]ms; 2.Check DiagData[7F 27 24]Within[50]ms; | L16: Pass
A17: 11 | B17: 1.General 2.DiagnosticServices | C17: Diag_0x27_Phy_011 | D17: Failure to comply with the secure access process: sending the key first, then requesting the seed - cross level | E17: High | F17: 陈亚-80025578 | G17: Based on analysis of requirements | H17: 1.Power On; | I17: 1.Send DiagBy[Physical]Data[10 03]; 2.Send DiagBy[Physical]Data[27 04]; 3.Send DiagBy[Physical]Data[27 01]AndCheckResp[PositiveResponse]; | J17: 1.Check DiagData[50 03 XX XX XX XX]Within[50]ms; 2.Check DiagData[7F 27 24]Within[50]ms; | K17: 不支持27 03，这里要回复NRC 12，而不是PositiveResponse | L17: Fail
A18: 12 | B18: 1.General 2.DiagnosticServices | C18: Diag_0x27_Phy_012 | D18: Repeated seed requests return the same seed data - PositiveResponse | E18: High | F18: 陈亚-80025578 | G18: Based on analysis of requirements | H18: 1.Power On; | I18: 1.Send DiagBy[Physical]Data[10 03]; 2.Send DiagBy[Physical]Data[27 01]AndCheckResp[PositiveResponse]; 3.Send DiagBy[Physical]Data[27 01]AndCheckResp[PositiveResponse]; | J18: 1.Check DiagData[50 03 XX XX XX XX]Within[50]ms; | L18: Pass
A19: 13 | B19: 1.General 2.DiagnosticServices | C19: Diag_0x27_Phy_013 | D19: After successful unlock, request seed returns all zeros - PositiveResponse | E19: High | F19: 陈亚-80025578 | G19: Based on analysis of requirements | H19: 1.Power On; | I19: 1.Send DiagBy[Physical]Data[10 03]; 2.Send DiagBy[Physical]Data[27 01]AndCheckResp[PositiveResponse]; 3.Send Security Right KeyBy[Physical]Level[02]; 4.Send DiagBy[Physical]Data[27 01]AndCheckResp[PositiveResponse]; | J19: 1.Check DiagData[50 03 XX XX XX XX]Within[50]ms; 3.Check DiagData[67 02]Within[50]ms; | L19: Pass
A20: 1.3 Security Access Mechanism Test (APP) — Path A: Wrong Key
A21: 14 | B21: 1.General 2.DiagnosticServices | C21: Diag_0x27_Phy_014 | D21: Meets the maximum of 3 failed attempts (wrong key); does not meet the reverse test case with a lockout time of 10 seconds | E21: High | F21: 陈亚-80025578 | G21: Based on analysis of requirements | H21: 1.Power On; | I21: 1.Send DiagBy[Physical]Data[10 03]; 2.Send DiagBy[Physical]Data[27 01]AndCheckResp[PositiveResponse]; 3.Send Security Wrong KeyBy[Physical]Level[02]; 4.Send DiagBy[Physical]Data[27 01]AndCheckResp[PositiveResponse]; 5.Send Security Wrong KeyBy[Physical]Level[02]; 6.Send DiagBy[Physical]Data[27 01]AndCheckResp[PositiveResponse]; 7.Send Security Wrong KeyBy[Physical]Level[02]; 8.Send DiagBy[Physical]Data[27 01]AndCheckResp[7F 27 37]; | J21: 1.Check DiagData[50 03 XX XX XX XX]Within[50]ms; 3.Check DiagData[7F 27 35]Within[50]ms; 5.Check DiagData[7F 27 35]Within[50]ms; 7.Check DiagData[7F 27 36]Within[50]ms; | L21: Pass
A22: 15 | B22: 1.General 2.DiagnosticServices | C22: Diag_0x27_Phy_015 | D22: A PositiveResponse test case that meets a maximum of 3 failed attempts (wrong key) and a lockout duration of 10 seconds | E22: High | F22: 陈亚-80025578 | G22: Based on analysis of requirements | H22: 1.Power On; | I22: 1.Send DiagBy[Physical]Data[10 03]; 2.Send DiagBy[Physical]Data[27 01]AndCheckResp[PositiveResponse]; 3.Send Security Wrong KeyBy[Physical]Level[02]; 4.Send DiagBy[Physical]Data[27 01]AndCheckResp[PositiveResponse]; 5.Send Security Wrong KeyBy[Physical]Level[02]; 6.Send DiagBy[Physical]Data[27 01]AndCheckResp[PositiveResponse]; 7.Send Security Wrong KeyBy[Physical]Level[02]; 8.Delay[10000]ms; 9.Send DiagBy[Physical]Data[27 01]AndCheckResp[PositiveResponse]; | J22: 1.Check DiagData[50 03 XX XX XX XX]Within[50]ms; 3.Check DiagData[7F 27 35]Within[50]ms; 5.Check DiagData[7F 27 35]Within[50]ms; 7.Check DiagData[7F 27 36]Within[50]ms; | L22: Pass
A23: 16 | B23: 1.General 2.DiagnosticServices | C23: Diag_0x27_Phy_016 | D23: A negative test case where the maximum number of secure access attempts (with incorrect keys) is reached and the 10-second delay has not expired | E23: Low | F23: 陈亚-80025578 | G23: Based on analysis of requirements | H23: 1.Power On; | I23: 1.Send DiagBy[Physical]Data[10 03]; 2.Send DiagBy[Physical]Data[27 01]AndCheckResp[PositiveResponse]; 3.Send Security Wrong KeyBy[Physical]Level[02]; 4.Send DiagBy[Physical]Data[27 01]AndCheckResp[PositiveResponse]; 5.Send Security Wrong KeyBy[Physical]Level[02]; 6.Send DiagBy[Physical]Data[27 01]AndCheckResp[PositiveResponse]; 7.Send Security Wrong KeyBy[Physical]Level[02]; 8.Delay[5000]ms; 9.Send DiagBy[Physical]Data[27 01]AndCheckResp[7F 27 37]; | J23: 1.Check DiagData[50 03 XX XX XX XX]Within[50]ms; 3.Check DiagData[7F 27 35]Within[50]ms; 5.Check DiagData[7F 27 35]Within[50]ms; 7.Check DiagData[7F 27 36]Within[50]ms; | L23: Pass
A24: 17 | B24: 1.General 2.DiagnosticServices | C24: Diag_0x27_Phy_017 | D24: When the maximum number of safe access attempts (wrong key) = 4 is reached, successfully unlock once to reset counter | E24: High | F24: 陈亚-80025578 | G24: Based on analysis of requirements | H24: 1.Power On; | I24: 1.Send DiagBy[Physical]Data[10 03]; 2.Send DiagBy[Physical]Data[27 01]AndCheckResp[PositiveResponse]; 3.Send Security Wrong KeyBy[Physical]Level[02]; 4.Send DiagBy[Physical]Data[27 01]AndCheckResp[PositiveResponse]; 5.Send Security Wrong KeyBy[Physical]Level[02]; 6.Send DiagBy[Physical]Data[27 01]AndCheckResp[PositiveResponse]; 7.Send Security Right KeyBy[Physical]Level[02]; 8.Send DiagBy[Physical]Data[10 01]; 9.Send DiagBy[Physical]Data[10 03]; 10.Send DiagBy[Physical]Data[27 01]AndCheckResp[PositiveResponse]; 11.Send Security Wrong KeyBy[Physical]Level[02]; 12.Send DiagBy[Physical]Data[27 01]AndCheckResp[PositiveResponse]; 13.Send Security Wrong KeyBy[Physical]Level[02]; 14.Send DiagBy[Physical]Data[27 01]AndCheckResp[PositiveResponse]; 15.Send Security Wrong KeyBy[Physical]Level[02]; 16.Send DiagBy[Physical]Data[27 01]AndCheckResp[7F 27 37]; | J24: 1.Check DiagData[50 03 XX XX XX XX]Within[50]ms; 3.Check DiagData[7F 27 35]Within[50]ms; 5.Check DiagData[7F 27 35]Within[50]ms; 7.Check DiagData[67 02]Within[50]ms; 8.Check DiagData[50 01 XX XX XX XX]Within[50]ms; 9.Check DiagData[50 03 XX XX XX XX]Within[50]ms; 11.Check DiagData[7F 27 35]Within[50]ms; 13.Check DiagData[7F 27 35]Within[50]ms; 15.Check DiagData[7F 27 36]Within[50]ms; | L24: Pass
A25: 18 | B25: 1.General 2.DiagnosticServices | C25: Diag_0x27_Phy_018 | D25: SAcounter equals 3 after reset when FAAflag = True (wrong key path) - PositiveResponse | E25: High | F25: 陈亚-80025578 | G25: Based on analysis of requirements | H25: 1.Power On; | I25: 1.Send DiagBy[Physical]Data[10 03]; 2.Send DiagBy[Physical]Data[27 01]AndCheckResp[PositiveResponse]; 3.Send Security Wrong KeyBy[Physical]Level[02]; 4.Send DiagBy[Physical]Data[27 01]AndCheckResp[PositiveResponse]; 5.Send Security Wrong KeyBy[Physical]Level[02]; 6.Send DiagBy[Physical]Data[27 01]AndCheckResp[PositiveResponse]; 7.Send Security Wrong KeyBy[Physical]Level[02]; 8.Set Voltage[0]V; 9.Delay[1000]ms; 10.Set Voltage[12]V; 11.Delay[1000]ms; 12.Send DiagBy[Physical]Data[10 03]; 13.Send DiagBy[Physical]Data[27 01]AndCheckResp[7F 27 37]; | J25: 1.Check DiagData[50 03 XX XX XX XX]Within[50]ms; 3.Check DiagData[7F 27 35]Within[50]ms; 5.Check DiagData[7F 27 35]Within[50]ms; 7.Check DiagData[7F 27 36]Within[50]ms; 12.Check DiagData[50 03 XX XX XX XX]Within[50]ms; | L25: Pass
A26: 19 | B26: 1.General 2.DiagnosticServices | C26: Diag_0x27_Phy_019 | D26: Hardware reset enabled 10s delay time (wrong key path) - PositiveResponse | E26: High | F26: 陈亚-80025578 | G26: Based on analysis of requirements | H26: 1.Power On; | I26: 1.Send DiagBy[Physical]Data[10 03]; 2.Send DiagBy[Physical]Data[27 01]AndCheckResp[PositiveResponse]; 3.Send Security Wrong KeyBy[Physical]Level[02]; 4.Send DiagBy[Physical]Data[27 01]AndCheckResp[PositiveResponse]; 5.Send Security Wrong KeyBy[Physical]Level[02]; 6.Send DiagBy[Physical]Data[27 01]AndCheckResp[PositiveResponse]; 7.Send Security Wrong KeyBy[Physical]Level[02]; 8.Set Voltage[0]V; 9.Delay[1000]ms; 10.Set Voltage[12]V; 11.Delay[1000]ms; 12.Send DiagBy[Physical]Data[10 03]; 13.Delay[10000]ms; 14.Send DiagBy[Physical]Data[27 01]AndCheckResp[PositiveResponse]; | J26: 1.Check DiagData[50 03 XX XX XX XX]Within[50]ms; 3.Check DiagData[7F 27 35]Within[50]ms; 5.Check DiagData[7F 27 35]Within[50]ms; 7.Check DiagData[7F 27 36]Within[50]ms; 12.Check DiagData[50 03 XX XX XX XX]Within[50]ms; | L26: Pass
A27: 20 | B27: 1.General 2.DiagnosticServices | C27: Diag_0x27_Phy_020 | D27: Reverse test case for reaching the maximum number of safe access attempts (wrong key) and the 10-second delay - 4th attempt triggers lock | E27: High | F27: 陈亚-80025578 | G27: Based on analysis of requirements | H27: 1.Power On; | I27: 1.Send DiagBy[Physical]Data[10 03]; 2.Send DiagBy[Physical]Data[27 01]AndCheckResp[PositiveResponse]; 3.Send Security Wrong KeyBy[Physical]Level[02]; 4.Send DiagBy[Physical]Data[27 01]AndCheckResp[PositiveResponse]; 5.Send Security Wrong KeyBy[Physical]Level[02]; 6.Send DiagBy[Physical]Data[27 01]AndCheckResp[PositiveResponse]; 7.Send Security Wrong KeyBy[Physical]Level[02]; 8.Delay[10000]ms; 9.Send DiagBy[Physical]Data[27 01]AndCheckResp[PositiveResponse]; 10.Send Security Wrong KeyBy[Physical]Level[02]; 11.Send DiagBy[Physical]Data[27 01]AndCheckResp[7F 27 37]; | J27: 1.Check DiagData[50 03 XX XX XX XX]Within[50]ms; 3.Check DiagData[7F 27 35]Within[50]ms; 5.Check DiagData[7F 27 35]Within[50]ms; 7.Check DiagData[7F 27 36]Within[50]ms; 10.Check DiagData[7F 27 36]Within[50]ms; | L27: Pass
A28: 1.4 Security Access Mechanism Test (APP) — Path B: Consecutive Seed Request
A29: 21 | B29: 1.General 2.DiagnosticServices | C29: Diag_0x27_Phy_021 | D29: Meets the maximum of 3 failed attempts (request seed); does not meet the reverse test case with a lockout time of 10 seconds | E29: High | F29: 陈亚-80025578 | G29: Based on analysis of requirements | H29: 1.Power On; | I29: 1.Send DiagBy[Physical]Data[10 03]; 2.Send DiagBy[Physical]Data[27 01]AndCheckResp[PositiveResponse]; 3.Send DiagBy[Physical]Data[27 01]AndCheckResp[PositiveResponse]; 4.Send DiagBy[Physical]Data[27 01]AndCheckResp[PositiveResponse]; 5.Send DiagBy[Physical]Data[27 01]AndCheckResp[7F 27 36]; 6.Send DiagBy[Physical]Data[27 01]AndCheckResp[7F 27 37]; | J29: 1.Check DiagData[50 03 XX XX XX XX]Within[50]ms; | L29: Pass
A30: 22 | B30: 1.General 2.DiagnosticServices | C30: Diag_0x27_Phy_022 | D30: A PositiveResponse test case that meets a maximum of 3 failed attempts (request seed) and a lockout duration of 10 seconds | E30: High | F30: 陈亚-80025578 | G30: Based on analysis of requirements | H30: 1.Power On; | I30: 1.Send DiagBy[Physical]Data[10 03]; 2.Send DiagBy[Physical]Data[27 01]AndCheckResp[PositiveResponse]; 3.Send DiagBy[Physical]Data[27 01]AndCheckResp[PositiveResponse]; 4.Send DiagBy[Physical]Data[27 01]AndCheckResp[PositiveResponse]; 5.Send DiagBy[Physical]Data[27 01]AndCheckResp[7F 27 36]; 6.Delay[10000]ms; 7.Send DiagBy[Physical]Data[27 01]AndCheckResp[PositiveResponse]; | J30: 1.Check DiagData[50 03 XX XX XX XX]Within[50]ms; | L30: Pass
A31: 23 | B31: 1.General 2.DiagnosticServices | C31: Diag_0x27_Phy_023 | D31: A negative test case where the maximum number of secure access attempts (request seed) is reached and the 10-second delay has not expired | E31: High | F31: 陈亚-80025578 | G31: Based on analysis of requirements | H31: 1.Power On; | I31: 1.Send DiagBy[Physical]Data[10 03]; 2.Send DiagBy[Physical]Data[27 01]AndCheckResp[PositiveResponse]; 3.Send DiagBy[Physical]Data[27 01]AndCheckResp[PositiveResponse]; 4.Send DiagBy[Physical]Data[27 01]AndCheckResp[PositiveResponse]; 5.Send DiagBy[Physical]Data[27 01]AndCheckResp[7F 27 36]; 6.Delay[5000]ms; 7.Send DiagBy[Physical]Data[27 01]AndCheckResp[7F 27 37]; | J31: 1.Check DiagData[50 03 XX XX XX XX]Within[50]ms; | L31: Pass
A32: 24 | B32: 1.General 2.DiagnosticServices | C32: Diag_0x27_Phy_024 | D32: When the maximum number of safe access attempts (request seed) = 4 is reached, successfully unlock once to reset counter | E32: High | F32: 陈亚-80025578 | G32: Based on analysis of requirements | H32: 1.Power On; | I32: 1.Send DiagBy[Physical]Data[10 03]; 2.Send DiagBy[Physical]Data[27 01]AndCheckResp[PositiveResponse]; 3.Send DiagBy[Physical]Data[27 01]AndCheckResp[PositiveResponse]; 4.Send DiagBy[Physical]Data[27 01]AndCheckResp[PositiveResponse]; 5.Send Security Right KeyBy[Physical]Level[02]; 6.Send DiagBy[Physical]Data[10 01]; 7.Send DiagBy[Physical]Data[10 03]; 8.Send DiagBy[Physical]Data[27 01]AndCheckResp[PositiveResponse]; 9.Send DiagBy[Physical]Data[27 01]AndCheckResp[PositiveResponse]; 10.Send DiagBy[Physical]Data[27 01]AndCheckResp[PositiveResponse]; 11.Send DiagBy[Physical]Data[27 01]AndCheckResp[7F 27 36]; | J32: 1.Check DiagData[50 03 XX XX XX XX]Within[50]ms; 5.Check DiagData[67 02]Within[50]ms; 6.Check DiagData[50 01 XX XX XX XX]Within[50]ms; 7.Check DiagData[50 03 XX XX XX XX]Within[50]ms; | L32: Pass
A33: 25 | B33: 1.General 2.DiagnosticServices | C33: Diag_0x27_Phy_025 | D33: SAcounter equals 3 after reset when FAAflag = True (request seed path) - PositiveResponse | E33: High | F33: 陈亚-80025578 | G33: Based on analysis of requirements | H33: 1.Power On; | I33: 1.Send DiagBy[Physical]Data[10 03]; 2.Send DiagBy[Physical]Data[27 01]AndCheckResp[PositiveResponse]; 3.Send DiagBy[Physical]Data[27 01]AndCheckResp[PositiveResponse]; 4.Send DiagBy[Physical]Data[27 01]AndCheckResp[PositiveResponse]; 5.Send DiagBy[Physical]Data[27 01]AndCheckResp[7F 27 36]; 6.Set Voltage[0]V; 7.Delay[1000]ms; 8.Set Voltage[12]V; 9.Delay[1000]ms; 10.Send DiagBy[Physical]Data[10 03]; 11.Send DiagBy[Physical]Data[27 01]AndCheckResp[7F 27 37]; | J33: 1.Check DiagData[50 03 XX XX XX XX]Within[50]ms; 10.Check DiagData[50 03 XX XX XX XX]Within[50]ms; | L33: Pass
A34: 26 | B34: 1.General 2.DiagnosticServices | C34: Diag_0x27_Phy_026 | D34: Hardware reset enabled 10s delay time (request seed path) - PositiveResponse | E34: High | F34: 陈亚-80025578 | G34: Based on analysis of requirements | H34: 1.Power On; | I34: 1.Send DiagBy[Physical]Data[10 03]; 2.Send DiagBy[Physical]Data[27 01]AndCheckResp[PositiveResponse]; 3.Send DiagBy[Physical]Data[27 01]AndCheckResp[PositiveResponse]; 4.Send DiagBy[Physical]Data[27 01]AndCheckResp[PositiveResponse]; 5.Send DiagBy[Physical]Data[27 01]AndCheckResp[7F 27 36]; 6.Set Voltage[0]V; 7.Delay[1000]ms; 8.Set Voltage[12]V; 9.Delay[1000]ms; 10.Send DiagBy[Physical]Data[10 03]; 11.Delay[10000]ms; 12.Send DiagBy[Physical]Data[27 01]AndCheckResp[PositiveResponse]; | J34: 1.Check DiagData[50 03 XX XX XX XX]Within[50]ms; 10.Check DiagData[50 03 XX XX XX XX]Within[50]ms; | L34: Pass
A35: 27 | B35: 1.General 2.DiagnosticServices | C35: Diag_0x27_Phy_027 | D35: Reverse test case for reaching the maximum number of safe access attempts (request seed) and the 10-second delay - 4th attempt triggers lock | E35: High | F35: 陈亚-80025578 | G35: Based on analysis of requirements | H35: 1.Power On; | I35: 1.Send DiagBy[Physical]Data[10 03]; 2.Send DiagBy[Physical]Data[27 01]AndCheckResp[PositiveResponse]; 3.Send DiagBy[Physical]Data[27 01]AndCheckResp[PositiveResponse]; 4.Send DiagBy[Physical]Data[27 01]AndCheckResp[PositiveResponse]; 5.Send DiagBy[Physical]Data[27 01]AndCheckResp[7F 27 36]; 6.Delay[10000]ms; 7.Send DiagBy[Physical]Data[27 01]AndCheckResp[PositiveResponse]; 8.Send DiagBy[Physical]Data[27 01]AndCheckResp[PositiveResponse]; 9.Send DiagBy[Physical]Data[27 01]AndCheckResp[PositiveResponse]; 10.Send DiagBy[Physical]Data[27 01]AndCheckResp[7F 27 36]; | J35: 1.Check DiagData[50 03 XX XX XX XX]Within[50]ms; | L35: Pass
A36: 1.5 Secure Access Time Test (APP)
A37: 28 | B37: 1.General 2.DiagnosticServices | C37: Diag_0x27_Phy_028 | D37: Duration after unlocking: 5s - PositiveResponse Response Case-$27 | E37: High | F37: 陈亚-80025578 | G37: Based on analysis of requirements | H37: 1.Power On; | I37: 1.Send DiagBy[Physical]Data[10 03]; 2.Send DiagBy[Physical]Data[27 01]AndCheckResp[PositiveResponse]; 3.Send Security Right KeyBy[Physical]Level[02]; 4.Delay[4900]ms; 5.Send DiagBy[Physical]Data[3E 00]; 6.Delay[4900]ms; 7.Send DiagBy[Physical]Data[27 01]AndCheckResp[PositiveResponse]; | J37: 1.Check DiagData[50 03 XX XX XX XX]Within[50]ms; 3.Check DiagData[67 02]Within[50]ms; 5.Check DiagData[7E 00]Within[50]ms; | L37: Pass
A38: 1.6 ECU Reset Test (APP)
A39: 29 | B39: 1.General 2.DiagnosticServices | C39: Diag_0x27_Phy_029 | D39: ECU power reset Session returns to the DefaultSession PositiveResponseCase-$27 | E39: Low | F39: 陈亚-80025578 | G39: Based on analysis of requirements | H39: 1.Power On; | I39: 1.Send DiagBy[Physical]Data[10 03]; 2.Send DiagBy[Physical]Data[27 01]AndCheckResp[PositiveResponse]; 3.Send Security Right KeyBy[Physical]Level[02]; 4.Set Voltage[0]V; 5.Delay[1000]ms; 6.Set Voltage[12]V; 7.Delay[1000]ms; 8.Send DiagBy[Physical]Data[10 03]; 9.Send DiagBy[Physical]Data[27 01]AndCheckResp[PositiveResponse]; | J39: 1.Check DiagData[50 03 XX XX XX XX]Within[50]ms; 3.Check DiagData[67 02]Within[50]ms; 8.Check DiagData[50 03 XX XX XX XX]Within[50]ms; | L39: Pass
